Workbook

Sheet A
A3: Student Achievement Levels of Grade 10 - 11
A4: Name of the School | S4: Zone | AC4: Division
A5: Grade & Class | J5: Year | S5: Term
B6: Student ID | C6: Subjects | D6: Mathematics | F6: Science | H6: First Language | J6: English | L6: Religion | N6: History | P6: Basket Subject I | S6: Basket Subject II | V6: Basket Subject III | Y6: Student's Grade Total | AD6: Pass=P /Fail=F | AE6: Student's Group | AF6: Student's Total | AG6: Student's Average | AH6: Student's Position
C7: Student's Name | D7: M | E7: G | F7: M | G7: G | H7: M | I7: G | J7: M | K7: G | L7: M | M7: G | N7: M | O7: G | P7: M | Q7: G | R7: X | S7: M | T7: G | U7: X | V7: M | W7: G | X7: X | Y7: A | Z7: B | AA7: C | AB7: S | AC7: W
A8: 1 | E8: =IF(D8="","",IF(D8="ab","ab",IF(D8>=75,"A",(IF(D8>=65,"B",IF(D8>=50,"C",IF(D8>=40,"S","W"))))))) | G8: =IF(F8="","",IF(F8="ab","ab",IF(F8>=75,"A",(IF(F8>=65,"B",IF(F8>=50,"C",IF(F8>=40,"S","W"))))))) | I8: =IF(H8="","",IF(H8="ab","ab",IF(H8>=75,"A",(IF(H8>=65,"B",IF(H8>=50,"C",IF(H8>=40,"S","W"))))))) | K8: =IF(J8="","",IF(J8="ab","ab",IF(J8>=75,"A",(IF(J8>=65,"B",IF(J8>=50,"C",IF(J8>=40,"S","W"))))))) | M8: =IF(L8="","",IF(L8="ab","ab",IF(L8>=75,"A",(IF(L8>=65,"B",IF(L8>=50,"C",IF(L8>=40,"S","W"))))))) | O8: =IF(N8="","",IF(N8="ab","ab",IF(N8>=75,"A",(IF(N8>=65,"B",IF(N8>=50,"C",IF(N8>=40,"S","W"))))))) | Q8: =IF(P8="","",IF(P8="ab","ab",IF(P8>=75,"A",(IF(P8>=65,"B",IF(P8>=50,"C",IF(P8>=40,"S","W"))))))) | T8: =IF(S8="","",IF(S8="ab","ab",IF(S8>=75,"A",(IF(S8>=65,"B",IF(S8>=50,"C",IF(S8>=40,"S","W"))))))) | W8: =IF(V8="","",IF(V8="ab","ab",IF(V8>=75,"A",(IF(V8>=65,"B",IF(V8>=50,"C",IF(V8>=40,"S","W"))))))) | Y8: =IF(AND($D8="ab",$F8="ab",$H8="ab",$J8="ab",$L8="ab",$N8="ab",$P8="ab",$S8="ab",$V8="ab"),"-",IF(COUNT($D8:$W8)=0,"",(COUNTIF($D8:$W8,"A")))) | Z8: =IF(AND($D8="ab",$F8="ab",$H8="ab",$J8="ab",$L8="ab",$N8="ab",$P8="ab",$S8="ab",$V8="ab"),"-",IF(COUNT($D8:$W8)=0,"",(COUNTIF($D8:$W8,"B")))) | AA8: =IF(AND($D8="ab",$F8="ab",$H8="ab",$J8="ab",$L8="ab",$N8="ab",$P8="ab",$S8="ab",$V8="ab"),"-",IF(COUNT($D8:$W8)=0,"",(COUNTIF($D8:$W8,"C")))) | AB8: =IF(AND($D8="ab",$F8="ab",$H8="ab",$J8="ab",$L8="ab",$N8="ab",$P8="ab",$S8="ab",$V8="ab"),"-",IF(COUNT($D8:$W8)=0,"",(COUNTIF($D8:$W8,"S")))) | AC8: =IF(AND($D8="ab",$F8="ab",$H8="ab",$J8="ab",$L8="ab",$N8="ab",$P8="ab",$S8="ab",$V8="ab"),"-",IF(COUNT($D8:$W8)=0,"",(COUNTIF($D8:$W8,"W")))) | AD8: =IF(AND(D8="ab",F8="ab",H8="ab",J8="ab",L8="ab",N8="ab",P8="ab",S8="ab",V8="ab"),"ab",IF(AND(Y8="",Z8="",AA8="",AB8="",AC8=""),"",IF(AND((D8>=40),(H8>=40),(Y8+Z8+AA8+AB8)>=6,(Y8+Z8+AA8)>=3),"P","F"))) | AE8: =IF(AD8="","",IF(AD8="P","P",IF(AND(AD8="F",H8>=40,D8>=40,(Y8+Z8+AA8+AB8)>=6,(Y8+Z8+AA8)=2),"Q1",IF(AND(AD8="F",(OR(H8>=40,D8>=40)),(Y8+Z8+AA8+AB8)>=5,(Y8+Z8+AA8)>=3),"Q2",IF((COUNTIF(D8:X8,">=40"))>=5,"R1",IF((COUNTIF(D8:X8,">=20"))>=5,"R2","F")))))) | AF8: =IF(AND(D8="",F8="",H8="",J8="",L8="",N8="",P8="",S8="",V8=""),"",IF(AND(D8="ab",F8="ab",H8="ab",J8="ab",L8="ab",N8="ab",P8="ab",S8="ab",V8="ab"),"ab",IF(COUNT(D8:W8)=0,"",(SUM(D8:V8))))) | AG8: =IF(AF8="","",IF(AF8="ab","ab",IF(AF8=0,0,(AVERAGE(D8:V8))))) | AH8: =IF(AF8="","",IF(AF8="ab","ab",(RANK(AF8,$AF$8:$AF$62))))
A9: 2 | E9: =IF(D9="","",IF(D9="ab","ab",IF(D9>=75,"A",(IF(D9>=65,"B",IF(D9>=50,"C",IF(D9>=40,"S","W"))))))) | G9: =IF(F9="","",IF(F9="ab","ab",IF(F9>=75,"A",(IF(F9>=65,"B",IF(F9>=50,"C",IF(F9>=40,"S","W"))))))) | I9: =IF(H9="","",IF(H9="ab","ab",IF(H9>=75,"A",(IF(H9>=65,"B",IF(H9>=50,"C",IF(H9>=40,"S","W"))))))) | K9: =IF(J9="","",IF(J9="ab","ab",IF(J9>=75,"A",(IF(J9>=65,"B",IF(J9>=50,"C",IF(J9>=40,"S","W"))))))) | M9: =IF(L9="","",IF(L9="ab","ab",IF(L9>=75,"A",(IF(L9>=65,"B",IF(L9>=50,"C",IF(L9>=40,"S","W"))))))) | O9: =IF(N9="","",IF(N9="ab","ab",IF(N9>=75,"A",(IF(N9>=65,"B",IF(N9>=50,"C",IF(N9>=40,"S","W"))))))) | Q9: =IF(P9="","",IF(P9="ab","ab",IF(P9>=75,"A",(IF(P9>=65,"B",IF(P9>=50,"C",IF(P9>=40,"S","W"))))))) | T9: =IF(S9="","",IF(S9="ab","ab",IF(S9>=75,"A",(IF(S9>=65,"B",IF(S9>=50,"C",IF(S9>=40,"S","W"))))))) | W9: =IF(V9="","",IF(V9="ab","ab",IF(V9>=75,"A",(IF(V9>=65,"B",IF(V9>=50,"C",IF(V9>=40,"S","W"))))))) | Y9: =IF(AND($D9="ab",$F9="ab",$H9="ab",$J9="ab",$L9="ab",$N9="ab",$P9="ab",$S9="ab",$V9="ab"),"-",IF(COUNT($D9:$W9)=0,"",(COUNTIF($D9:$W9,"A")))) | Z9: =IF(AND($D9="ab",$F9="ab",$H9="ab",$J9="ab",$L9="ab",$N9="ab",$P9="ab",$S9="ab",$V9="ab"),"-",IF(COUNT($D9:$W9)=0,"",(COUNTIF($D9:$W9,"B")))) | AA9: =IF(AND($D9="ab",$F9="ab",$H9="ab",$J9="ab",$L9="ab",$N9="ab",$P9="ab",$S9="ab",$V9="ab"),"-",IF(COUNT($D9:$W9)=0,"",(COUNTIF($D9:$W9,"C")))) | AB9: =IF(AND($D9="ab",$F9="ab",$H9="ab",$J9="ab",$L9="ab",$N9="ab",$P9="ab",$S9="ab",$V9="ab"),"-",IF(COUNT($D9:$W9)=0,"",(COUNTIF($D9:$W9,"S")))) | AC9: =IF(AND($D9="ab",$F9="ab",$H9="ab",$J9="ab",$L9="ab",$N9="ab",$P9="ab",$S9="ab",$V9="ab"),"-",IF(COUNT($D9:$W9)=0,"",(COUNTIF($D9:$W9,"W")))) | AD9: =IF(AND(D9="ab",F9="ab",H9="ab",J9="ab",L9="ab",N9="ab",P9="ab",S9="ab",V9="ab"),"ab",IF(AND(Y9="",Z9="",AA9="",AB9="",AC9=""),"",IF(AND((D9>=40),(H9>=40),(Y9+Z9+AA9+AB9)>=6,(Y9+Z9+AA9)>=3),"P","F"))) | AE9: =IF(AD9="","",IF(AD9="P","P",IF(AND(AD9="F",H9>=40,D9>=40,(Y9+Z9+AA9+AB9)>=6,(Y9+Z9+AA9)=2),"Q1",IF(AND(AD9="F",(OR(H9>=40,D9>=40)),(Y9+Z9+AA9+AB9)>=5,(Y9+Z9+AA9)>=3),"Q2",IF((COUNTIF(D9:X9,">=40"))>=5,"R1",IF((COUNTIF(D9:X9,">=20"))>=5,"R2","F")))))) | AF9: =IF(AND(D9="",F9="",H9="",J9="",L9="",N9="",P9="",S9="",V9=""),"",IF(AND(D9="ab",F9="ab",H9="ab",J9="ab",L9="ab",N9="ab",P9="ab",S9="ab",V9="ab"),"ab",IF(COUNT(D9:W9)=0,"",(SUM(D9:V9))))) | AG9: =IF(AF9="","",IF(AF9="ab","ab",IF(AF9=0,0,(AVERAGE(D9:V9))))) | AH9: =IF(AF9="","",IF(AF9="ab","ab",(RANK(AF9,$AF$8:$AF$62))))
A10: 3 | E10: =IF(D10="","",IF(D10="ab","ab",IF(D10>=75,"A",(IF(D10>=65,"B",IF(D10>=50,"C",IF(D10>=40,"S","W"))))))) | G10: =IF(F10="","",IF(F10="ab","ab",IF(F10>=75,"A",(IF(F10>=65,"B",IF(F10>=50,"C",IF(F10>=40,"S","W"))))))) | I10: =IF(H10="","",IF(H10="ab","ab",IF(H10>=75,"A",(IF(H10>=65,"B",IF(H10>=50,"C",IF(H10>=40,"S","W"))))))) | K10: =IF(J10="","",IF(J10="ab","ab",IF(J10>=75,"A",(IF(J10>=65,"B",IF(J10>=50,"C",IF(J10>=40,"S","W"))))))) | M10: =IF(L10="","",IF(L10="ab","ab",IF(L10>=75,"A",(IF(L10>=65,"B",IF(L10>=50,"C",IF(L10>=40,"S","W"))))))) | O10: =IF(N10="","",IF(N10="ab","ab",IF(N10>=75,"A",(IF(N10>=65,"B",IF(N10>=50,"C",IF(N10>=40,"S","W"))))))) | Q10: =IF(P10="","",IF(P10="ab","ab",IF(P10>=75,"A",(IF(P10>=65,"B",IF(P10>=50,"C",IF(P10>=40,"S","W"))))))) | T10: =IF(S10="","",IF(S10="ab","ab",IF(S10>=75,"A",(IF(S10>=65,"B",IF(S10>=50,"C",IF(S10>=40,"S","W"))))))) | W10: =IF(V10="","",IF(V10="ab","ab",IF(V10>=75,"A",(IF(V10>=65,"B",IF(V10>=50,"C",IF(V10>=40,"S","W"))))))) | Y10: =IF(AND($D10="ab",$F10="ab",$H10="ab",$J10="ab",$L10="ab",$N10="ab",$P10="ab",$S10="ab",$V10="ab"),"-",IF(COUNT($D10:$W10)=0,"",(COUNTIF($D10:$W10,"A")))) | Z10: =IF(AND($D10="ab",$F10="ab",$H10="ab",$J10="ab",$L10="ab",$N10="ab",$P10="ab",$S10="ab",$V10="ab"),"-",IF(COUNT($D10:$W10)=0,"",(COUNTIF($D10:$W10,"B")))) | AA10: =IF(AND($D10="ab",$F10="ab",$H10="ab",$J10="ab",$L10="ab",$N10="ab",$P10="ab",$S10="ab",$V10="ab"),"-",IF(COUNT($D10:$W10)=0,"",(COUNTIF($D10:$W10,"C")))) | AB10: =IF(AND($D10="ab",$F10="ab",$H10="ab",$J10="ab",$L10="ab",$N10="ab",$P10="ab",$S10="ab",$V10="ab"),"-",IF(COUNT($D10:$W10)=0,"",(COUNTIF($D10:$W10,"S")))) | AC10: =IF(AND($D10="ab",$F10="ab",$H10="ab",$J10="ab",$L10="ab",$N10="ab",$P10="ab",$S10="ab",$V10="ab"),"-",IF(COUNT($D10:$W10)=0,"",(COUNTIF($D10:$W10,"W")))) | AD10: =IF(AND(D10="ab",F10="ab",H10="ab",J10="ab",L10="ab",N10="ab",P10="ab",S10="ab",V10="ab"),"ab",IF(AND(Y10="",Z10="",AA10="",AB10="",AC10=""),"",IF(AND((D10>=40),(H10>=40),(Y10+Z10+AA10+AB10)>=6,(Y10+Z10+AA10)>=3),"P","F"))) | AE10: =IF(AD10="","",IF(AD10="P","P",IF(AND(AD10="F",H10>=40,D10>=40,(Y10+Z10+AA10+AB10)>=6,(Y10+Z10+AA10)=2),"Q1",IF(AND(AD10="F",(OR(H10>=40,D10>=40)),(Y10+Z10+AA10+AB10)>=5,(Y10+Z10+AA10)>=3),"Q2",IF((COUNTIF(D10:X10,">=40"))>=5,"R1",IF((COUNTIF(D10:X10,">=20"))>=5,"R2","F")))))) | AF10: =IF(AND(D10="",F10="",H10="",J10="",L10="",N10="",P10="",S10="",V10=""),"",IF(AND(D10="ab",F10="ab",H10="ab",J10="ab",L10="ab",N10="ab",P10="ab",S10="ab",V10="ab"),"ab",IF(COUNT(D10:W10)=0,"",(SUM(D10:V10))))) | AG10: =IF(AF10="","",IF(AF10="ab","ab",IF(AF10=0,0,(AVERAGE(D10:V10))))) | AH10: =IF(AF10="","",IF(AF10="ab","ab",(RANK(AF10,$AF$8:$AF$62))))
A11: 4 | E11: =IF(D11="","",IF(D11="ab","ab",IF(D11>=75,"A",(IF(D11>=65,"B",IF(D11>=50,"C",IF(D11>=40,"S","W"))))))) | G11: =IF(F11="","",IF(F11="ab","ab",IF(F11>=75,"A",(IF(F11>=65,"B",IF(F11>=50,"C",IF(F11>=40,"S","W"))))))) | I11: =IF(H11="","",IF(H11="ab","ab",IF(H11>=75,"A",(IF(H11>=65,"B",IF(H11>=50,"C",IF(H11>=40,"S","W"))))))) | K11: =IF(J11="","",IF(J11="ab","ab",IF(J11>=75,"A",(IF(J11>=65,"B",IF(J11>=50,"C",IF(J11>=40,"S","W"))))))) | M11: =IF(L11="","",IF(L11="ab","ab",IF(L11>=75,"A",(IF(L11>=65,"B",IF(L11>=50,"C",IF(L11>=40,"S","W"))))))) | O11: =IF(N11="","",IF(N11="ab","ab",IF(N11>=75,"A",(IF(N11>=65,"B",IF(N11>=50,"C",IF(N11>=40,"S","W"))))))) | Q11: =IF(P11="","",IF(P11="ab","ab",IF(P11>=75,"A",(IF(P11>=65,"B",IF(P11>=50,"C",IF(P11>=40,"S","W"))))))) | T11: =IF(S11="","",IF(S11="ab","ab",IF(S11>=75,"A",(IF(S11>=65,"B",IF(S11>=50,"C",IF(S11>=40,"S","W"))))))) | W11: =IF(V11="","",IF(V11="ab","ab",IF(V11>=75,"A",(IF(V11>=65,"B",IF(V11>=50,"C",IF(V11>=40,"S","W"))))))) | Y11: =IF(AND($D11="ab",$F11="ab",$H11="ab",$J11="ab",$L11="ab",$N11="ab",$P11="ab",$S11="ab",$V11="ab"),"-",IF(COUNT($D11:$W11)=0,"",(COUNTIF($D11:$W11,"A")))) | Z11: =IF(AND($D11="ab",$F11="ab",$H11="ab",$J11="ab",$L11="ab",$N11="ab",$P11="ab",$S11="ab",$V11="ab"),"-",IF(COUNT($D11:$W11)=0,"",(COUNTIF($D11:$W11,"B")))) | AA11: =IF(AND($D11="ab",$F11="ab",$H11="ab",$J11="ab",$L11="ab",$N11="ab",$P11="ab",$S11="ab",$V11="ab"),"-",IF(COUNT($D11:$W11)=0,"",(COUNTIF($D11:$W11,"C")))) | AB11: =IF(AND($D11="ab",$F11="ab",$H11="ab",$J11="ab",$L11="ab",$N11="ab",$P11="ab",$S11="ab",$V11="ab"),"-",IF(COUNT($D11:$W11)=0,"",(COUNTIF($D11:$W11,"S")))) | AC11: =IF(AND($D11="ab",$F11="ab",$H11="ab",$J11="ab",$L11="ab",$N11="ab",$P11="ab",$S11="ab",$V11="ab"),"-",IF(COUNT($D11:$W11)=0,"",(COUNTIF($D11:$W11,"W")))) | AD11: =IF(AND(D11="ab",F11="ab",H11="ab",J11="ab",L11="ab",N11="ab",P11="ab",S11="ab",V11="ab"),"ab",IF(AND(Y11="",Z11="",AA11="",AB11="",AC11=""),"",IF(AND((D11>=40),(H11>=40),(Y11+Z11+AA11+AB11)>=6,(Y11+Z11+AA11)>=3),"P","F"))) | AE11: =IF(AD11="","",IF(AD11="P","P",IF(AND(AD11="F",H11>=40,D11>=40,(Y11+Z11+AA11+AB11)>=6,(Y11+Z11+AA11)=2),"Q1",IF(AND(AD11="F",(OR(H11>=40,D11>=40)),(Y11+Z11+AA11+AB11)>=5,(Y11+Z11+AA11)>=3),"Q2",IF((COUNTIF(D11:X11,">=40"))>=5,"R1",IF((COUNTIF(D11:X11,">=20"))>=5,"R2","F")))))) | AF11: =IF(AND(D11="",F11="",H11="",J11="",L11="",N11="",P11="",S11="",V11=""),"",IF(AND(D11="ab",F11="ab",H11="ab",J11="ab",L11="ab",N11="ab",P11="ab",S11="ab",V11="ab"),"ab",IF(COUNT(D11:W11)=0,"",(SUM(D11:V11))))) | AG11: =IF(AF11="","",IF(AF11="ab","ab",IF(AF11=0,0,(AVERAGE(D11:V11))))) | AH11: =IF(AF11="","",IF(AF11="ab","ab",(RANK(AF11,$AF$8:$AF$62))))
A12: 5 | E12: =IF(D12="","",IF(D12="ab","ab",IF(D12>=75,"A",(IF(D12>=65,"B",IF(D12>=50,"C",IF(D12>=40,"S","W"))))))) | G12: =IF(F12="","",IF(F12="ab","ab",IF(F12>=75,"A",(IF(F12>=65,"B",IF(F12>=50,"C",IF(F12>=40,"S","W"))))))) | I12: =IF(H12="","",IF(H12="ab","ab",IF(H12>=75,"A",(IF(H12>=65,"B",IF(H12>=50,"C",IF(H12>=40,"S","W"))))))) | K12: =IF(J12="","",IF(J12="ab","ab",IF(J12>=75,"A",(IF(J12>=65,"B",IF(J12>=50,"C",IF(J12>=40,"S","W"))))))) | M12: =IF(L12="","",IF(L12="ab","ab",IF(L12>=75,"A",(IF(L12>=65,"B",IF(L12>=50,"C",IF(L12>=40,"S","W"))))))) | O12: =IF(N12="","",IF(N12="ab","ab",IF(N12>=75,"A",(IF(N12>=65,"B",IF(N12>=50,"C",IF(N12>=40,"S","W"))))))) | Q12: =IF(P12="","",IF(P12="ab","ab",IF(P12>=75,"A",(IF(P12>=65,"B",IF(P12>=50,"C",IF(P12>=40,"S","W"))))))) | T12: =IF(S12="","",IF(S12="ab","ab",IF(S12>=75,"A",(IF(S12>=65,"B",IF(S12>=50,"C",IF(S12>=40,"S","W"))))))) | W12: =IF(V12="","",IF(V12="ab","ab",IF(V12>=75,"A",(IF(V12>=65,"B",IF(V12>=50,"C",IF(V12>=40,"S","W"))))))) | Y12: =IF(AND($D12="ab",$F12="ab",$H12="ab",$J12="ab",$L12="ab",$N12="ab",$P12="ab",$S12="ab",$V12="ab"),"-",IF(COUNT($D12:$W12)=0,"",(COUNTIF($D12:$W12,"A")))) | Z12: =IF(AND($D12="ab",$F12="ab",$H12="ab",$J12="ab",$L12="ab",$N12="ab",$P12="ab",$S12="ab",$V12="ab"),"-",IF(COUNT($D12:$W12)=0,"",(COUNTIF($D12:$W12,"B")))) | AA12: =IF(AND($D12="ab",$F12="ab",$H12="ab",$J12="ab",$L12="ab",$N12="ab",$P12="ab",$S12="ab",$V12="ab"),"-",IF(COUNT($D12:$W12)=0,"",(COUNTIF($D12:$W12,"C")))) | AB12: =IF(AND($D12="ab",$F12="ab",$H12="ab",$J12="ab",$L12="ab",$N12="ab",$P12="ab",$S12="ab",$V12="ab"),"-",IF(COUNT($D12:$W12)=0,"",(COUNTIF($D12:$W12,"S")))) | AC12: =IF(AND($D12="ab",$F12="ab",$H12="ab",$J12="ab",$L12="ab",$N12="ab",$P12="ab",$S12="ab",$V12="ab"),"-",IF(COUNT($D12:$W12)=0,"",(COUNTIF($D12:$W12,"W")))) | AD12: =IF(AND(D12="ab",F12="ab",H12="ab",J12="ab",L12="ab",N12="ab",P12="ab",S12="ab",V12="ab"),"ab",IF(AND(Y12="",Z12="",AA12="",AB12="",AC12=""),"",IF(AND((D12>=40),(H12>=40),(Y12+Z12+AA12+AB12)>=6,(Y12+Z12+AA12)>=3),"P","F"))) | AE12: =IF(AD12="","",IF(AD12="P","P",IF(AND(AD12="F",H12>=40,D12>=40,(Y12+Z12+AA12+AB12)>=6,(Y12+Z12+AA12)=2),"Q1",IF(AND(AD12="F",(OR(H12>=40,D12>=40)),(Y12+Z12+AA12+AB12)>=5,(Y12+Z12+AA12)>=3),"Q2",IF((COUNTIF(D12:X12,">=40"))>=5,"R1",IF((COUNTIF(D12:X12,">=20"))>=5,"R2","F")))))) | AF12: =IF(AND(D12="",F12="",H12="",J12="",L12="",N12="",P12="",S12="",V12=""),"",IF(AND(D12="ab",F12="ab",H12="ab",J12="ab",L12="ab",N12="ab",P12="ab",S12="ab",V12="ab"),"ab",IF(COUNT(D12:W12)=0,"",(SUM(D12:V12))))) | AG12: =IF(AF12="","",IF(AF12="ab","ab",IF(AF12=0,0,(AVERAGE(D12:V12))))) | AH12: =IF(AF12="","",IF(AF12="ab","ab",(RANK(AF12,$AF$8:$AF$62))))
A13: 6 | E13: =IF(D13="","",IF(D13="ab","ab",IF(D13>=75,"A",(IF(D13>=65,"B",IF(D13>=50,"C",IF(D13>=40,"S","W"))))))) | G13: =IF(F13="","",IF(F13="ab","ab",IF(F13>=75,"A",(IF(F13>=65,"B",IF(F13>=50,"C",IF(F13>=40,"S","W"))))))) | I13: =IF(H13="","",IF(H13="ab","ab",IF(H13>=75,"A",(IF(H13>=65,"B",IF(H13>=50,"C",IF(H13>=40,"S","W"))))))) | K13: =IF(J13="","",IF(J13="ab","ab",IF(J13>=75,"A",(IF(J13>=65,"B",IF(J13>=50,"C",IF(J13>=40,"S","W"))))))) | M13: =IF(L13="","",IF(L13="ab","ab",IF(L13>=75,"A",(IF(L13>=65,"B",IF(L13>=50,"C",IF(L13>=40,"S","W"))))))) | O13: =IF(N13="","",IF(N13="ab","ab",IF(N13>=75,"A",(IF(N13>=65,"B",IF(N13>=50,"C",IF(N13>=40,"S","W"))))))) | Q13: =IF(P13="","",IF(P13="ab","ab",IF(P13>=75,"A",(IF(P13>=65,"B",IF(P13>=50,"C",IF(P13>=40,"S","W"))))))) | T13: =IF(S13="","",IF(S13="ab","ab",IF(S13>=75,"A",(IF(S13>=65,"B",IF(S13>=50,"C",IF(S13>=40,"S","W"))))))) | W13: =IF(V13="","",IF(V13="ab","ab",IF(V13>=75,"A",(IF(V13>=65,"B",IF(V13>=50,"C",IF(V13>=40,"S","W"))))))) | Y13: =IF(AND($D13="ab",$F13="ab",$H13="ab",$J13="ab",$L13="ab",$N13="ab",$P13="ab",$S13="ab",$V13="ab"),"-",IF(COUNT($D13:$W13)=0,"",(COUNTIF($D13:$W13,"A")))) | Z13: =IF(AND($D13="ab",$F13="ab",$H13="ab",$J13="ab",$L13="ab",$N13="ab",$P13="ab",$S13="ab",$V13="ab"),"-",IF(COUNT($D13:$W13)=0,"",(COUNTIF($D13:$W13,"B")))) | AA13: =IF(AND($D13="ab",$F13="ab",$H13="ab",$J13="ab",$L13="ab",$N13="ab",$P13="ab",$S13="ab",$V13="ab"),"-",IF(COUNT($D13:$W13)=0,"",(COUNTIF($D13:$W13,"C")))) | AB13: =IF(AND($D13="ab",$F13="ab",$H13="ab",$J13="ab",$L13="ab",$N13="ab",$P13="ab",$S13="ab",$V13="ab"),"-",IF(COUNT($D13:$W13)=0,"",(COUNTIF($D13:$W13,"S")))) | AC13: =IF(AND($D13="ab",$F13="ab",$H13="ab",$J13="ab",$L13="ab",$N13="ab",$P13="ab",$S13="ab",$V13="ab"),"-",IF(COUNT($D13:$W13)=0,"",(COUNTIF($D13:$W13,"W")))) | AD13: =IF(AND(D13="ab",F13="ab",H13="ab",J13="ab",L13="ab",N13="ab",P13="ab",S13="ab",V13="ab"),"ab",IF(AND(Y13="",Z13="",AA13="",AB13="",AC13=""),"",IF(AND((D13>=40),(H13>=40),(Y13+Z13+AA13+AB13)>=6,(Y13+Z13+AA13)>=3),"P","F"))) | AE13: =IF(AD13="","",IF(AD13="P","P",IF(AND(AD13="F",H13>=40,D13>=40,(Y13+Z13+AA13+AB13)>=6,(Y13+Z13+AA13)=2),"Q1",IF(AND(AD13="F",(OR(H13>=40,D13>=40)),(Y13+Z13+AA13+AB13)>=5,(Y13+Z13+AA13)>=3),"Q2",IF((COUNTIF(D13:X13,">=40"))>=5,"R1",IF((COUNTIF(D13:X13,">=20"))>=5,"R2","F")))))) | AF13: =IF(AND(D13="",F13="",H13="",J13="",L13="",N13="",P13="",S13="",V13=""),"",IF(AND(D13="ab",F13="ab",H13="ab",J13="ab",L13="ab",N13="ab",P13="ab",S13="ab",V13="ab"),"ab",IF(COUNT(D13:W13)=0,"",(SUM(D13:V13))))) | AG13: =IF(AF13="","",IF(AF13="ab","ab",IF(AF13=0,0,(AVERAGE(D13:V13))))) | AH13: =IF(AF13="","",IF(AF13="ab","ab",(RANK(AF13,$AF$8:$AF$62))))
A14: 7 | E14: =IF(D14="","",IF(D14="ab","ab",IF(D14>=75,"A",(IF(D14>=65,"B",IF(D14>=50,"C",IF(D14>=40,"S","W"))))))) | G14: =IF(F14="","",IF(F14="ab","ab",IF(F14>=75,"A",(IF(F14>=65,"B",IF(F14>=50,"C",IF(F14>=40,"S","W"))))))) | I14: =IF(H14="","",IF(H14="ab","ab",IF(H14>=75,"A",(IF(H14>=65,"B",IF(H14>=50,"C",IF(H14>=40,"S","W"))))))) | K14: =IF(J14="","",IF(J14="ab","ab",IF(J14>=75,"A",(IF(J14>=65,"B",IF(J14>=50,"C",IF(J14>=40,"S","W"))))))) | M14: =IF(L14="","",IF(L14="ab","ab",IF(L14>=75,"A",(IF(L14>=65,"B",IF(L14>=50,"C",IF(L14>=40,"S","W"))))))) | O14: =IF(N14="","",IF(N14="ab","ab",IF(N14>=75,"A",(IF(N14>=65,"B",IF(N14>=50,"C",IF(N14>=40,"S","W"))))))) | Q14: =IF(P14="","",IF(P14="ab","ab",IF(P14>=75,"A",(IF(P14>=65,"B",IF(P14>=50,"C",IF(P14>=40,"S","W"))))))) | T14: =IF(S14="","",IF(S14="ab","ab",IF(S14>=75,"A",(IF(S14>=65,"B",IF(S14>=50,"C",IF(S14>=40,"S","W"))))))) | W14: =IF(V14="","",IF(V14="ab","ab",IF(V14>=75,"A",(IF(V14>=65,"B",IF(V14>=50,"C",IF(V14>=40,"S","W"))))))) | Y14: =IF(AND($D14="ab",$F14="ab",$H14="ab",$J14="ab",$L14="ab",$N14="ab",$P14="ab",$S14="ab",$V14="ab"),"-",IF(COUNT($D14:$W14)=0,"",(COUNTIF($D14:$W14,"A")))) | Z14: =IF(AND($D14="ab",$F14="ab",$H14="ab",$J14="ab",$L14="ab",$N14="ab",$P14="ab",$S14="ab",$V14="ab"),"-",IF(COUNT($D14:$W14)=0,"",(COUNTIF($D14:$W14,"B")))) | AA14: =IF(AND($D14="ab",$F14="ab",$H14="ab",$J14="ab",$L14="ab",$N14="ab",$P14="ab",$S14="ab",$V14="ab"),"-",IF(COUNT($D14:$W14)=0,"",(COUNTIF($D14:$W14,"C")))) | AB14: =IF(AND($D14="ab",$F14="ab",$H14="ab",$J14="ab",$L14="ab",$N14="ab",$P14="ab",$S14="ab",$V14="ab"),"-",IF(COUNT($D14:$W14)=0,"",(COUNTIF($D14:$W14,"S")))) | AC14: =IF(AND($D14="ab",$F14="ab",$H14="ab",$J14="ab",$L14="ab",$N14="ab",$P14="ab",$S14="ab",$V14="ab"),"-",IF(COUNT($D14:$W14)=0,"",(COUNTIF($D14:$W14,"W")))) | AD14: =IF(AND(D14="ab",F14="ab",H14="ab",J14="ab",L14="ab",N14="ab",P14="ab",S14="ab",V14="ab"),"ab",IF(AND(Y14="",Z14="",AA14="",AB14="",AC14=""),"",IF(AND((D14>=40),(H14>=40),(Y14+Z14+AA14+AB14)>=6,(Y14+Z14+AA14)>=3),"P","F"))) | AE14: =IF(AD14="","",IF(AD14="P","P",IF(AND(AD14="F",H14>=40,D14>=40,(Y14+Z14+AA14+AB14)>=6,(Y14+Z14+AA14)=2),"Q1",IF(AND(AD14="F",(OR(H14>=40,D14>=40)),(Y14+Z14+AA14+AB14)>=5,(Y14+Z14+AA14)>=3),"Q2",IF((COUNTIF(D14:X14,">=40"))>=5,"R1",IF((COUNTIF(D14:X14,">=20"))>=5,"R2","F")))))) | AF14: =IF(AND(D14="",F14="",H14="",J14="",L14="",N14="",P14="",S14="",V14=""),"",IF(AND(D14="ab",F14="ab",H14="ab",J14="ab",L14="ab",N14="ab",P14="ab",S14="ab",V14="ab"),"ab",IF(COUNT(D14:W14)=0,"",(SUM(D14:V14))))) | AG14: =IF(AF14="","",IF(AF14="ab","ab",IF(AF14=0,0,(AVERAGE(D14:V14))))) | AH14: =IF(AF14="","",IF(AF14="ab","ab",(RANK(AF14,$AF$8:$AF$62))))
A15: 8 | E15: =IF(D15="","",IF(D15="ab","ab",IF(D15>=75,"A",(IF(D15>=65,"B",IF(D15>=50,"C",IF(D15>=40,"S","W"))))))) | G15: =IF(F15="","",IF(F15="ab","ab",IF(F15>=75,"A",(IF(F15>=65,"B",IF(F15>=50,"C",IF(F15>=40,"S","W"))))))) | I15: =IF(H15="","",IF(H15="ab","ab",IF(H15>=75,"A",(IF(H15>=65,"B",IF(H15>=50,"C",IF(H15>=40,"S","W"))))))) | K15: =IF(J15="","",IF(J15="ab","ab",IF(J15>=75,"A",(IF(J15>=65,"B",IF(J15>=50,"C",IF(J15>=40,"S","W"))))))) | M15: =IF(L15="","",IF(L15="ab","ab",IF(L15>=75,"A",(IF(L15>=65,"B",IF(L15>=50,"C",IF(L15>=40,"S","W"))))))) | O15: =IF(N15="","",IF(N15="ab","ab",IF(N15>=75,"A",(IF(N15>=65,"B",IF(N15>=50,"C",IF(N15>=40,"S","W"))))))) | Q15: =IF(P15="","",IF(P15="ab","ab",IF(P15>=75,"A",(IF(P15>=65,"B",IF(P15>=50,"C",IF(P15>=40,"S","W"))))))) | T15: =IF(S15="","",IF(S15="ab","ab",IF(S15>=75,"A",(IF(S15>=65,"B",IF(S15>=50,"C",IF(S15>=40,"S","W"))))))) | W15: =IF(V15="","",IF(V15="ab","ab",IF(V15>=75,"A",(IF(V15>=65,"B",IF(V15>=50,"C",IF(V15>=40,"S","W"))))))) | Y15: =IF(AND($D15="ab",$F15="ab",$H15="ab",$J15="ab",$L15="ab",$N15="ab",$P15="ab",$S15="ab",$V15="ab"),"-",IF(COUNT($D15:$W15)=0,"",(COUNTIF($D15:$W15,"A")))) | Z15: =IF(AND($D15="ab",$F15="ab",$H15="ab",$J15="ab",$L15="ab",$N15="ab",$P15="ab",$S15="ab",$V15="ab"),"-",IF(COUNT($D15:$W15)=0,"",(COUNTIF($D15:$W15,"B")))) | AA15: =IF(AND($D15="ab",$F15="ab",$H15="ab",$J15="ab",$L15="ab",$N15="ab",$P15="ab",$S15="ab",$V15="ab"),"-",IF(COUNT($D15:$W15)=0,"",(COUNTIF($D15:$W15,"C")))) | AB15: =IF(AND($D15="ab",$F15="ab",$H15="ab",$J15="ab",$L15="ab",$N15="ab",$P15="ab",$S15="ab",$V15="ab"),"-",IF(COUNT($D15:$W15)=0,"",(COUNTIF($D15:$W15,"S")))) | AC15: =IF(AND($D15="ab",$F15="ab",$H15="ab",$J15="ab",$L15="ab",$N15="ab",$P15="ab",$S15="ab",$V15="ab"),"-",IF(COUNT($D15:$W15)=0,"",(COUNTIF($D15:$W15,"W")))) | AD15: =IF(AND(D15="ab",F15="ab",H15="ab",J15="ab",L15="ab",N15="ab",P15="ab",S15="ab",V15="ab"),"ab",IF(AND(Y15="",Z15="",AA15="",AB15="",AC15=""),"",IF(AND((D15>=40),(H15>=40),(Y15+Z15+AA15+AB15)>=6,(Y15+Z15+AA15)>=3),"P","F"))) | AE15: =IF(AD15="","",IF(AD15="P","P",IF(AND(AD15="F",H15>=40,D15>=40,(Y15+Z15+AA15+AB15)>=6,(Y15+Z15+AA15)=2),"Q1",IF(AND(AD15="F",(OR(H15>=40,D15>=40)),(Y15+Z15+AA15+AB15)>=5,(Y15+Z15+AA15)>=3),"Q2",IF((COUNTIF(D15:X15,">=40"))>=5,"R1",IF((COUNTIF(D15:X15,">=20"))>=5,"R2","F")))))) | AF15: =IF(AND(D15="",F15="",H15="",J15="",L15="",N15="",P15="",S15="",V15=""),"",IF(AND(D15="ab",F15="ab",H15="ab",J15="ab",L15="ab",N15="ab",P15="ab",S15="ab",V15="ab"),"ab",IF(COUNT(D15:W15)=0,"",(SUM(D15:V15))))) | AG15: =IF(AF15="","",IF(AF15="ab","ab",IF(AF15=0,0,(AVERAGE(D15:V15))))) | AH15: =IF(AF15="","",IF(AF15="ab","ab",(RANK(AF15,$AF$8:$AF$62))))
A16: 9 | E16: =IF(D16="","",IF(D16="ab","ab",IF(D16>=75,"A",(IF(D16>=65,"B",IF(D16>=50,"C",IF(D16>=40,"S","W"))))))) | G16: =IF(F16="","",IF(F16="ab","ab",IF(F16>=75,"A",(IF(F16>=65,"B",IF(F16>=50,"C",IF(F16>=40,"S","W"))))))) | I16: =IF(H16="","",IF(H16="ab","ab",IF(H16>=75,"A",(IF(H16>=65,"B",IF(H16>=50,"C",IF(H16>=40,"S","W"))))))) | K16: =IF(J16="","",IF(J16="ab","ab",IF(J16>=75,"A",(IF(J16>=65,"B",IF(J16>=50,"C",IF(J16>=40,"S","W"))))))) | M16: =IF(L16="","",IF(L16="ab","ab",IF(L16>=75,"A",(IF(L16>=65,"B",IF(L16>=50,"C",IF(L16>=40,"S","W"))))))) | O16: =IF(N16="","",IF(N16="ab","ab",IF(N16>=75,"A",(IF(N16>=65,"B",IF(N16>=50,"C",IF(N16>=40,"S","W"))))))) | Q16: =IF(P16="","",IF(P16="ab","ab",IF(P16>=75,"A",(IF(P16>=65,"B",IF(P16>=50,"C",IF(P16>=40,"S","W"))))))) | T16: =IF(S16="","",IF(S16="ab","ab",IF(S16>=75,"A",(IF(S16>=65,"B",IF(S16>=50,"C",IF(S16>=40,"S","W"))))))) | W16: =IF(V16="","",IF(V16="ab","ab",IF(V16>=75,"A",(IF(V16>=65,"B",IF(V16>=50,"C",IF(V16>=40,"S","W"))))))) | Y16: =IF(AND($D16="ab",$F16="ab",$H16="ab",$J16="ab",$L16="ab",$N16="ab",$P16="ab",$S16="ab",$V16="ab"),"-",IF(COUNT($D16:$W16)=0,"",(COUNTIF($D16:$W16,"A")))) | Z16: =IF(AND($D16="ab",$F16="ab",$H16="ab",$J16="ab",$L16="ab",$N16="ab",$P16="ab",$S16="ab",$V16="ab"),"-",IF(COUNT($D16:$W16)=0,"",(COUNTIF($D16:$W16,"B")))) | AA16: =IF(AND($D16="ab",$F16="ab",$H16="ab",$J16="ab",$L16="ab",$N16="ab",$P16="ab",$S16="ab",$V16="ab"),"-",IF(COUNT($D16:$W16)=0,"",(COUNTIF($D16:$W16,"C")))) | AB16: =IF(AND($D16="ab",$F16="ab",$H16="ab",$J16="ab",$L16="ab",$N16="ab",$P16="ab",$S16="ab",$V16="ab"),"-",IF(COUNT($D16:$W16)=0,"",(COUNTIF($D16:$W16,"S")))) | AC16: =IF(AND($D16="ab",$F16="ab",$H16="ab",$J16="ab",$L16="ab",$N16="ab",$P16="ab",$S16="ab",$V16="ab"),"-",IF(COUNT($D16:$W16)=0,"",(COUNTIF($D16:$W16,"W")))) | AD16: =IF(AND(D16="ab",F16="ab",H16="ab",J16="ab",L16="ab",N16="ab",P16="ab",S16="ab",V16="ab"),"ab",IF(AND(Y16="",Z16="",AA16="",AB16="",AC16=""),"",IF(AND((D16>=40),(H16>=40),(Y16+Z16+AA16+AB16)>=6,(Y16+Z16+AA16)>=3),"P","F"))) | AE16: =IF(AD16="","",IF(AD16="P","P",IF(AND(AD16="F",H16>=40,D16>=40,(Y16+Z16+AA16+AB16)>=6,(Y16+Z16+AA16)=2),"Q1",IF(AND(AD16="F",(OR(H16>=40,D16>=40)),(Y16+Z16+AA16+AB16)>=5,(Y16+Z16+AA16)>=3),"Q2",IF((COUNTIF(D16:X16,">=40"))>=5,"R1",IF((COUNTIF(D16:X16,">=20"))>=5,"R2","F")))))) | AF16: =IF(AND(D16="",F16="",H16="",J16="",L16="",N16="",P16="",S16="",V16=""),"",IF(AND(D16="ab",F16="ab",H16="ab",J16="ab",L16="ab",N16="ab",P16="ab",S16="ab",V16="ab"),"ab",IF(COUNT(D16:W16)=0,"",(SUM(D16:V16))))) | AG16: =IF(AF16="","",IF(AF16="ab","ab",IF(AF16=0,0,(AVERAGE(D16:V16))))) | AH16: =IF(AF16="","",IF(AF16="ab","ab",(RANK(AF16,$AF$8:$AF$62))))
A17: 10 | E17: =IF(D17="","",IF(D17="ab","ab",IF(D17>=75,"A",(IF(D17>=65,"B",IF(D17>=50,"C",IF(D17>=40,"S","W"))))))) | G17: =IF(F17="","",IF(F17="ab","ab",IF(F17>=75,"A",(IF(F17>=65,"B",IF(F17>=50,"C",IF(F17>=40,"S","W"))))))) | I17: =IF(H17="","",IF(H17="ab","ab",IF(H17>=75,"A",(IF(H17>=65,"B",IF(H17>=50,"C",IF(H17>=40,"S","W"))))))) | K17: =IF(J17="","",IF(J17="ab","ab",IF(J17>=75,"A",(IF(J17>=65,"B",IF(J17>=50,"C",IF(J17>=40,"S","W"))))))) | M17: =IF(L17="","",IF(L17="ab","ab",IF(L17>=75,"A",(IF(L17>=65,"B",IF(L17>=50,"C",IF(L17>=40,"S","W"))))))) | O17: =IF(N17="","",IF(N17="ab","ab",IF(N17>=75,"A",(IF(N17>=65,"B",IF(N17>=50,"C",IF(N17>=40,"S","W"))))))) | Q17: =IF(P17="","",IF(P17="ab","ab",IF(P17>=75,"A",(IF(P17>=65,"B",IF(P17>=50,"C",IF(P17>=40,"S","W"))))))) | T17: =IF(S17="","",IF(S17="ab","ab",IF(S17>=75,"A",(IF(S17>=65,"B",IF(S17>=50,"C",IF(S17>=40,"S","W"))))))) | W17: =IF(V17="","",IF(V17="ab","ab",IF(V17>=75,"A",(IF(V17>=65,"B",IF(V17>=50,"C",IF(V17>=40,"S","W"))))))) | Y17: =IF(AND($D17="ab",$F17="ab",$H17="ab",$J17="ab",$L17="ab",$N17="ab",$P17="ab",$S17="ab",$V17="ab"),"-",IF(COUNT($D17:$W17)=0,"",(COUNTIF($D17:$W17,"A")))) | Z17: =IF(AND($D17="ab",$F17="ab",$H17="ab",$J17="ab",$L17="ab",$N17="ab",$P17="ab",$S17="ab",$V17="ab"),"-",IF(COUNT($D17:$W17)=0,"",(COUNTIF($D17:$W17,"B")))) | AA17: =IF(AND($D17="ab",$F17="ab",$H17="ab",$J17="ab",$L17="ab",$N17="ab",$P17="ab",$S17="ab",$V17="ab"),"-",IF(COUNT($D17:$W17)=0,"",(COUNTIF($D17:$W17,"C")))) | AB17: =IF(AND($D17="ab",$F17="ab",$H17="ab",$J17="ab",$L17="ab",$N17="ab",$P17="ab",$S17="ab",$V17="ab"),"-",IF(COUNT($D17:$W17)=0,"",(COUNTIF($D17:$W17,"S")))) | AC17: =IF(AND($D17="ab",$F17="ab",$H17="ab",$J17="ab",$L17="ab",$N17="ab",$P17="ab",$S17="ab",$V17="ab"),"-",IF(COUNT($D17:$W17)=0,"",(COUNTIF($D17:$W17,"W")))) | AD17: =IF(AND(D17="ab",F17="ab",H17="ab",J17="ab",L17="ab",N17="ab",P17="ab",S17="ab",V17="ab"),"ab",IF(AND(Y17="",Z17="",AA17="",AB17="",AC17=""),"",IF(AND((D17>=40),(H17>=40),(Y17+Z17+AA17+AB17)>=6,(Y17+Z17+AA17)>=3),"P","F"))) | AE17: =IF(AD17="","",IF(AD17="P","P",IF(AND(AD17="F",H17>=40,D17>=40,(Y17+Z17+AA17+AB17)>=6,(Y17+Z17+AA17)=2),"Q1",IF(AND(AD17="F",(OR(H17>=40,D17>=40)),(Y17+Z17+AA17+AB17)>=5,(Y17+Z17+AA17)>=3),"Q2",IF((COUNTIF(D17:X17,">=40"))>=5,"R1",IF((COUNTIF(D17:X17,">=20"))>=5,"R2","F")))))) | AF17: =IF(AND(D17="",F17="",H17="",J17="",L17="",N17="",P17="",S17="",V17=""),"",IF(AND(D17="ab",F17="ab",H17="ab",J17="ab",L17="ab",N17="ab",P17="ab",S17="ab",V17="ab"),"ab",IF(COUNT(D17:W17)=0,"",(SUM(D17:V17))))) | AG17: =IF(AF17="","",IF(AF17="ab","ab",IF(AF17=0,0,(AVERAGE(D17:V17))))) | AH17: =IF(AF17="","",IF(AF17="ab","ab",(RANK(AF17,$AF$8:$AF$62))))
A18: 11 | E18: =IF(D18="","",IF(D18="ab","ab",IF(D18>=75,"A",(IF(D18>=65,"B",IF(D18>=50,"C",IF(D18>=40,"S","W"))))))) | G18: =IF(F18="","",IF(F18="ab","ab",IF(F18>=75,"A",(IF(F18>=65,"B",IF(F18>=50,"C",IF(F18>=40,"S","W"))))))) | I18: =IF(H18="","",IF(H18="ab","ab",IF(H18>=75,"A",(IF(H18>=65,"B",IF(H18>=50,"C",IF(H18>=40,"S","W"))))))) | K18: =IF(J18="","",IF(J18="ab","ab",IF(J18>=75,"A",(IF(J18>=65,"B",IF(J18>=50,"C",IF(J18>=40,"S","W"))))))) | M18: =IF(L18="","",IF(L18="ab","ab",IF(L18>=75,"A",(IF(L18>=65,"B",IF(L18>=50,"C",IF(L18>=40,"S","W"))))))) | O18: =IF(N18="","",IF(N18="ab","ab",IF(N18>=75,"A",(IF(N18>=65,"B",IF(N18>=50,"C",IF(N18>=40,"S","W"))))))) | Q18: =IF(P18="","",IF(P18="ab","ab",IF(P18>=75,"A",(IF(P18>=65,"B",IF(P18>=50,"C",IF(P18>=40,"S","W"))))))) | T18: =IF(S18="","",IF(S18="ab","ab",IF(S18>=75,"A",(IF(S18>=65,"B",IF(S18>=50,"C",IF(S18>=40,"S","W"))))))) | W18: =IF(V18="","",IF(V18="ab","ab",IF(V18>=75,"A",(IF(V18>=65,"B",IF(V18>=50,"C",IF(V18>=40,"S","W"))))))) | Y18: =IF(AND($D18="ab",$F18="ab",$H18="ab",$J18="ab",$L18="ab",$N18="ab",$P18="ab",$S18="ab",$V18="ab"),"-",IF(COUNT($D18:$W18)=0,"",(COUNTIF($D18:$W18,"A")))) | Z18: =IF(AND($D18="ab",$F18="ab",$H18="ab",$J18="ab",$L18="ab",$N18="ab",$P18="ab",$S18="ab",$V18="ab"),"-",IF(COUNT($D18:$W18)=0,"",(COUNTIF($D18:$W18,"B")))) | AA18: =IF(AND($D18="ab",$F18="ab",$H18="ab",$J18="ab",$L18="ab",$N18="ab",$P18="ab",$S18="ab",$V18="ab"),"-",IF(COUNT($D18:$W18)=0,"",(COUNTIF($D18:$W18,"C")))) | AB18: =IF(AND($D18="ab",$F18="ab",$H18="ab",$J18="ab",$L18="ab",$N18="ab",$P18="ab",$S18="ab",$V18="ab"),"-",IF(COUNT($D18:$W18)=0,"",(COUNTIF($D18:$W18,"S")))) | AC18: =IF(AND($D18="ab",$F18="ab",$H18="ab",$J18="ab",$L18="ab",$N18="ab",$P18="ab",$S18="ab",$V18="ab"),"-",IF(COUNT($D18:$W18)=0,"",(COUNTIF($D18:$W18,"W")))) | AD18: =IF(AND(D18="ab",F18="ab",H18="ab",J18="ab",L18="ab",N18="ab",P18="ab",S18="ab",V18="ab"),"ab",IF(AND(Y18="",Z18="",AA18="",AB18="",AC18=""),"",IF(AND((D18>=40),(H18>=40),(Y18+Z18+AA18+AB18)>=6,(Y18+Z18+AA18)>=3),"P","F"))) | AE18: =IF(AD18="","",IF(AD18="P","P",IF(AND(AD18="F",H18>=40,D18>=40,(Y18+Z18+AA18+AB18)>=6,(Y18+Z18+AA18)=2),"Q1",IF(AND(AD18="F",(OR(H18>=40,D18>=40)),(Y18+Z18+AA18+AB18)>=5,(Y18+Z18+AA18)>=3),"Q2",IF((COUNTIF(D18:X18,">=40"))>=5,"R1",IF((COUNTIF(D18:X18,">=20"))>=5,"R2","F")))))) | AF18: =IF(AND(D18="",F18="",H18="",J18="",L18="",N18="",P18="",S18="",V18=""),"",IF(AND(D18="ab",F18="ab",H18="ab",J18="ab",L18="ab",N18="ab",P18="ab",S18="ab",V18="ab"),"ab",IF(COUNT(D18:W18)=0,"",(SUM(D18:V18))))) | AG18: =IF(AF18="","",IF(AF18="ab","ab",IF(AF18=0,0,(AVERAGE(D18:V18))))) | AH18: =IF(AF18="","",IF(AF18="ab","ab",(RANK(AF18,$AF$8:$AF$62))))
A19: 12 | E19: =IF(D19="","",IF(D19="ab","ab",IF(D19>=75,"A",(IF(D19>=65,"B",IF(D19>=50,"C",IF(D19>=40,"S","W"))))))) | G19: =IF(F19="","",IF(F19="ab","ab",IF(F19>=75,"A",(IF(F19>=65,"B",IF(F19>=50,"C",IF(F19>=40,"S","W"))))))) | I19: =IF(H19="","",IF(H19="ab","ab",IF(H19>=75,"A",(IF(H19>=65,"B",IF(H19>=50,"C",IF(H19>=40,"S","W"))))))) | K19: =IF(J19="","",IF(J19="ab","ab",IF(J19>=75,"A",(IF(J19>=65,"B",IF(J19>=50,"C",IF(J19>=40,"S","W"))))))) | M19: =IF(L19="","",IF(L19="ab","ab",IF(L19>=75,"A",(IF(L19>=65,"B",IF(L19>=50,"C",IF(L19>=40,"S","W"))))))) | O19: =IF(N19="","",IF(N19="ab","ab",IF(N19>=75,"A",(IF(N19>=65,"B",IF(N19>=50,"C",IF(N19>=40,"S","W"))))))) | Q19: =IF(P19="","",IF(P19="ab","ab",IF(P19>=75,"A",(IF(P19>=65,"B",IF(P19>=50,"C",IF(P19>=40,"S","W"))))))) | T19: =IF(S19="","",IF(S19="ab","ab",IF(S19>=75,"A",(IF(S19>=65,"B",IF(S19>=50,"C",IF(S19>=40,"S","W"))))))) | W19: =IF(V19="","",IF(V19="ab","ab",IF(V19>=75,"A",(IF(V19>=65,"B",IF(V19>=50,"C",IF(V19>=40,"S","W"))))))) | Y19: =IF(AND($D19="ab",$F19="ab",$H19="ab",$J19="ab",$L19="ab",$N19="ab",$P19="ab",$S19="ab",$V19="ab"),"-",IF(COUNT($D19:$W19)=0,"",(COUNTIF($D19:$W19,"A")))) | Z19: =IF(AND($D19="ab",$F19="ab",$H19="ab",$J19="ab",$L19="ab",$N19="ab",$P19="ab",$S19="ab",$V19="ab"),"-",IF(COUNT($D19:$W19)=0,"",(COUNTIF($D19:$W19,"B")))) | AA19: =IF(AND($D19="ab",$F19="ab",$H19="ab",$J19="ab",$L19="ab",$N19="ab",$P19="ab",$S19="ab",$V19="ab"),"-",IF(COUNT($D19:$W19)=0,"",(COUNTIF($D19:$W19,"C")))) | AB19: =IF(AND($D19="ab",$F19="ab",$H19="ab",$J19="ab",$L19="ab",$N19="ab",$P19="ab",$S19="ab",$V19="ab"),"-",IF(COUNT($D19:$W19)=0,"",(COUNTIF($D19:$W19,"S")))) | AC19: =IF(AND($D19="ab",$F19="ab",$H19="ab",$J19="ab",$L19="ab",$N19="ab",$P19="ab",$S19="ab",$V19="ab"),"-",IF(COUNT($D19:$W19)=0,"",(COUNTIF($D19:$W19,"W")))) | AD19: =IF(AND(D19="ab",F19="ab",H19="ab",J19="ab",L19="ab",N19="ab",P19="ab",S19="ab",V19="ab"),"ab",IF(AND(Y19="",Z19="",AA19="",AB19="",AC19=""),"",IF(AND((D19>=40),(H19>=40),(Y19+Z19+AA19+AB19)>=6,(Y19+Z19+AA19)>=3),"P","F"))) | AE19: =IF(AD19="","",IF(AD19="P","P",IF(AND(AD19="F",H19>=40,D19>=40,(Y19+Z19+AA19+AB19)>=6,(Y19+Z19+AA19)=2),"Q1",IF(AND(AD19="F",(OR(H19>=40,D19>=40)),(Y19+Z19+AA19+AB19)>=5,(Y19+Z19+AA19)>=3),"Q2",IF((COUNTIF(D19:X19,">=40"))>=5,"R1",IF((COUNTIF(D19:X19,">=20"))>=5,"R2","F")))))) | AF19: =IF(AND(D19="",F19="",H19="",J19="",L19="",N19="",P19="",S19="",V19=""),"",IF(AND(D19="ab",F19="ab",H19="ab",J19="ab",L19="ab",N19="ab",P19="ab",S19="ab",V19="ab"),"ab",IF(COUNT(D19:W19)=0,"",(SUM(D19:V19))))) | AG19: =IF(AF19="","",IF(AF19="ab","ab",IF(AF19=0,0,(AVERAGE(D19:V19))))) | AH19: =IF(AF19="","",IF(AF19="ab","ab",(RANK(AF19,$AF$8:$AF$62))))
... A62: 55 | E62: =IF(D62="","",IF(D62="ab","ab",IF(D62>=75,"A",(IF(D62>=65,"B",IF(D62>=50,"C",IF(D62>=40,"S","W"))))))) | G62: =IF(F62="","",IF(F62="ab","ab",IF(F62>=75,"A",(IF(F62>=65,"B",IF(F62>=50,"C",IF(F62>=40,"S","W"))))))) | I62: =IF(H62="","",IF(H62="ab","ab",IF(H62>=75,"A",(IF(H62>=65,"B",IF(H62>=50,"C",IF(H62>=40,"S","W"))))))) | K62: =IF(J62="","",IF(J62="ab","ab",IF(J62>=75,"A",(IF(J62>=65,"B",IF(J62>=50,"C",IF(J62>=40,"S","W"))))))) | M62: =IF(L62="","",IF(L62="ab","ab",IF(L62>=75,"A",(IF(L62>=65,"B",IF(L62>=50,"C",IF(L62>=40,"S","W"))))))) | O62: =IF(N62="","",IF(N62="ab","ab",IF(N62>=75,"A",(IF(N62>=65,"B",IF(N62>=50,"C",IF(N62>=40,"S","W"))))))) | Q62: =IF(P62="","",IF(P62="ab","ab",IF(P62>=75,"A",(IF(P62>=65,"B",IF(P62>=50,"C",IF(P62>=40,"S","W"))))))) | T62: =IF(S62="","",IF(S62="ab","ab",IF(S62>=75,"A",(IF(S62>=65,"B",IF(S62>=50,"C",IF(S62>=40,"S","W"))))))) | W62: =IF(V62="","",IF(V62="ab","ab",IF(V62>=75,"A",(IF(V62>=65,"B",IF(V62>=50,"C",IF(V62>=40,"S","W"))))))) | Y62: =IF(AND($D62="ab",$F62="ab",$H62="ab",$J62="ab",$L62="ab",$N62="ab",$P62="ab",$S62="ab",$V62="ab"),"-",IF(COUNT($D62:$W62)=0,"",(COUNTIF($D62:$W62,"A")))) | Z62: =IF(AND($D62="ab",$F62="ab",$H62="ab",$J62="ab",$L62="ab",$N62="ab",$P62="ab",$S62="ab",$V62="ab"),"-",IF(COUNT($D62:$W62)=0,"",(COUNTIF($D62:$W62,"B")))) | AA62: =IF(AND($D62="ab",$F62="ab",$H62="ab",$J62="ab",$L62="ab",$N62="ab",$P62="ab",$S62="ab",$V62="ab"),"-",IF(COUNT($D62:$W62)=0,"",(COUNTIF($D62:$W62,"C")))) | AB62: =IF(AND($D62="ab",$F62="ab",$H62="ab",$J62="ab",$L62="ab",$N62="ab",$P62="ab",$S62="ab",$V62="ab"),"-",IF(COUNT($D62:$W62)=0,"",(COUNTIF($D62:$W62,"S")))) | AC62: =IF(AND($D62="ab",$F62="ab",$H62="ab",$J62="ab",$L62="ab",$N62="ab",$P62="ab",$S62="ab",$V62="ab"),"-",IF(COUNT($D62:$W62)=0,"",(COUNTIF($D62:$W62,"W")))) | AD62: =IF(AND(D62="ab",F62="ab",H62="ab",J62="ab",L62="ab",N62="ab",P62="ab",S62="ab",V62="ab"),"ab",IF(AND(Y62="",Z62="",AA62="",AB62="",AC62=""),"",IF(AND((D62>=40),(H62>=40),(Y62+Z62+AA62+AB62)>=6,(Y62+Z62+AA62)>=3),"P","F"))) | AE62: =IF(AD62="","",IF(AD62="P","P",IF(AND(AD62="F",H62>=40,D62>=40,(Y62+Z62+AA62+AB62)>=6,(Y62+Z62+AA62)=2),"Q1",IF(AND(AD62="F",(OR(H62>=40,D62>=40)),(Y62+Z62+AA62+AB62)>=5,(Y62+Z62+AA62)>=3),"Q2",IF((COUNTIF(D62:X62,">=40"))>=5,"R1",IF((COUNTIF(D62:X62,">=20"))>=5,"R2","F")))))) | AF62: =IF(AND(D62="",F62="",H62="",J62="",L62="",N62="",P62="",S62="",V62=""),"",IF(AND(D62="ab",F62="ab",H62="ab",J62="ab",L62="ab",N62="ab",P62="ab",S62="ab",V62="ab"),"ab",IF(COUNT(D62:W62)=0,"",(SUM(D62:V62))))) | AG62: =IF(AF62="","",IF(AF62="ab","ab",IF(AF62=0,0,(AVERAGE(D62:V62))))) | AH62: =IF(AF62="","",IF(AF62="ab","ab",(RANK(AF62,$AF$8:$AF$62))))
A63: Total | D63: =IF(COUNTA(D8:D62)=0,"",(SUM(D8:D62))) | F63: =IF(COUNTA(F8:F62)=0,"",(SUM(F8:F62))) | H63: =IF(COUNTA(H8:H62)=0,"",(SUM(H8:H62))) | J63: =IF(COUNTA(J8:J62)=0,"",(SUM(J8:J62))) | L63: =IF(COUNTA(L8:L62)=0,"",(SUM(L8:L62))) | N63: =IF(COUNTA(N8:N62)=0,"",(SUM(N8:N62))) | P63: =IF(COUNTA(P8:P62)=0,"",(SUM(P8:P62))) | S63: =IF(COUNTA(S8:S62)=0,"",(SUM(S8:S62))) | V63: =IF(COUNTA(V8:V62)=0,"",(SUM(V8:V62))) | Y63: Total 'ab's | AD63: =IF(OR(COUNTIF(AD8:AD62,"P")<>0,COUNTIF(AD8:AD62,"F")<>0,COUNTIF(AD8:AD62,"ab")<>0),(COUNTIF(AD8:AD62,"ab")),"") | AE63: =IF(OR(COUNTIF(AE8:AE62,"P")<>0,COUNTIF(AE8:AE62,"F")<>0,COUNTIF(AE8:AE62,"ab")<>0,COUNTIF(AE8:AE62,"Q1")<>0,COUNTIF(AE8:AE62,"Q2")<>0,COUNTIF(AE8:AE62,"R1")<>0,COUNTIF(AE8:AE62,"R2")<>0),(COUNTIF(AE8:AE62,"ab")),"") | AF63: Total 'ab's
A64: Subject Average | D64: =IF(D63="","",IF(D63=0,0,AVERAGE(D8:D62))) | F64: =IF(F63="","",IF(F63=0,0,AVERAGE(F8:F62))) | H64: =IF(H63="","",IF(H63=0,0,AVERAGE(H8:H62))) | J64: =IF(J63="","",IF(J63=0,0,AVERAGE(J8:J62))) | L64: =IF(L63="","",IF(L63=0,0,AVERAGE(L8:L62))) | N64: =IF(N63="","",IF(N63=0,0,AVERAGE(N8:N62))) | P64: =IF(P63="","",IF(P63=0,0,AVERAGE(P8:P62))) | S64: =IF(S63="","",IF(S63=0,0,AVERAGE(S8:S62))) | V64: =IF(V63="","",IF(V63=0,0,AVERAGE(V8:V62))) | Y64: Total 'P's | AD64: =IF(OR(COUNTIF(AD8:AD62,"P")<>0,COUNTIF(AD8:AD62,"F")<>0,COUNTIF(AD8:AD62,"ab")<>0),(COUNTIF(AD8:AD62,"P")),"") | AE64: =IF(OR(COUNTIF(AE8:AE62,"P")<>0,COUNTIF(AE8:AE62,"F")<>0,COUNTIF(AE8:AE62,"ab")<>0,COUNTIF(AE8:AE62,"Q1")<>0,COUNTIF(AE8:AE62,"Q2")<>0,COUNTIF(AE8:AE62,"R1")<>0,COUNTIF(AE8:AE62,"R2")<>0),(COUNTIF(AE8:AE62,"P")),"") | AF64: Total 'P's
Y65: Total 'F's | AD65: =IF(OR(COUNTIF(AD8:AD62,"P")<>0,COUNTIF(AD8:AD62,"F")<>0,COUNTIF(AD8:AD62,"ab")<>0),(COUNTIF(AD8:AD62,"F")),"") | AE65: =IF(OR(COUNTIF(AE8:AE62,"P")<>0,COUNTIF(AE8:AE62,"F")<>0,COUNTIF(AE8:AE62,"ab")<>0,COUNTIF(AE8:AE62,"Q1")<>0,COUNTIF(AE8:AE62,"Q2")<>0,COUNTIF(AE8:AE62,"R1")<>0,COUNTIF(AE8:AE62,"R2")<>0),(COUNTIF(AE8:AE62,"Q1")),"") | AF65: Total 'Q1's
A66: Grades Total for Subjects | C66: A - 75 | E66: =IF(D$63="","",(COUNTIF(E$8:E$62,"A"))) | G66: =IF(F$63="","",(COUNTIF(G$8:G$62,"A"))) | I66: =IF(H$63="","",(COUNTIF(I$8:I$62,"A"))) | K66: =IF(J$63="","",(COUNTIF(K$8:K$62,"A"))) | M66: =IF(L$63="","",(COUNTIF(M$8:M$62,"A"))) | O66: =IF(N$63="","",(COUNTIF(O$8:O$62,"A"))) | Q66: =IF(P$63="","",(COUNTIF(Q$8:Q$62,"A"))) | T66: =IF(S$63="","",(COUNTIF(T$8:T$62,"A"))) | W66: =IF(V$63="","",(COUNTIF(W$8:W$62,"A"))) | Y66: =IF((COUNT($D66:$W66)=0),"",(SUM($D66:$W66))) | AE66: =IF(OR(COUNTIF(AE8:AE62,"P")<>0,COUNTIF(AE8:AE62,"F")<>0,COUNTIF(AE8:AE62,"ab")<>0,COUNTIF(AE8:AE62,"Q1")<>0,COUNTIF(AE8:AE62,"Q2")<>0,COUNTIF(AE8:AE62,"R1")<>0,COUNTIF(AE8:AE62,"R2")<>0),(COUNTIF(AE8:AE62,"Q2")),"") | AF66: Total 'Q2's
C67: B - 65 | E67: =IF(D$63="","",(COUNTIF(E$8:E$62,"B"))) | G67: =IF(F$63="","",(COUNTIF(G$8:G$62,"B"))) | I67: =IF(H$63="","",(COUNTIF(I$8:I$62,"B"))) | K67: =IF(J$63="","",(COUNTIF(K$8:K$62,"B"))) | M67: =IF(L$63="","",(COUNTIF(M$8:M$62,"B"))) | O67: =IF(N$63="","",(COUNTIF(O$8:O$62,"B"))) | Q67: =IF(P$63="","",(COUNTIF(Q$8:Q$62,"B"))) | T67: =IF(S$63="","",(COUNTIF(T$8:T$62,"B"))) | W67: =IF(V$63="","",(COUNTIF(W$8:W$62,"B"))) | Z67: =IF((COUNT($D67:$W67)=0),"",SUM($D67:$W67)) | AE67: =IF(OR(COUNTIF(AE8:AE62,"P")<>0,COUNTIF(AE8:AE62,"F")<>0,COUNTIF(AE8:AE62,"ab")<>0,COUNTIF(AE8:AE62,"Q1")<>0,COUNTIF(AE8:AE62,"Q2")<>0,COUNTIF(AE8:AE62,"R1")<>0,COUNTIF(AE8:AE62,"R2")<>0),(COUNTIF(AE8:AE62,"R1")),"") | AF67: Total 'R1's
C68: C - 50 | E68: =IF(D$63="","",(COUNTIF(E$8:E$62,"C"))) | G68: =IF(F$63="","",(COUNTIF(G$8:G$62,"C"))) | I68: =IF(H$63="","",(COUNTIF(I$8:I$62,"C"))) | K68: =IF(J$63="","",(COUNTIF(K$8:K$62,"C"))) | M68: =IF(L$63="","",(COUNTIF(M$8:M$62,"C"))) | O68: =IF(N$63="","",(COUNTIF(O$8:O$62,"C"))) | Q68: =IF(P$63="","",(COUNTIF(Q$8:Q$62,"C"))) | T68: =IF(S$63="","",(COUNTIF(T$8:T$62,"C"))) | W68: =IF(V$63="","",(COUNTIF(W$8:W$62,"C"))) | AA68: =IF((COUNT($D68:$W68)=0),"",SUM($D68:$W68)) | AE68: =IF(OR(COUNTIF(AE8:AE62,"P")<>0,COUNTIF(AE8:AE62,"F")<>0,COUNTIF(AE8:AE62,"ab")<>0,COUNTIF(AE8:AE62,"Q1")<>0,COUNTIF(AE8:AE62,"Q2")<>0,COUNTIF(AE8:AE62,"R1")<>0,COUNTIF(AE8:AE62,"R2")<>0),(COUNTIF(AE8:AE62,"R2")),"") | AF68: Total 'R2's
C69: S - 40 | E69: =IF(D$63="","",(COUNTIF(E$8:E$62,"S"))) | G69: =IF(F$63="","",(COUNTIF(G$8:G$62,"S"))) | I69: =IF(H$63="","",(COUNTIF(I$8:I$62,"S"))) | K69: =IF(J$63="","",(COUNTIF(K$8:K$62,"S"))) | M69: =IF(L$63="","",(COUNTIF(M$8:M$62,"S"))) | O69: =IF(N$63="","",(COUNTIF(O$8:O$62,"S"))) | Q69: =IF(P$63="","",(COUNTIF(Q$8:Q$62,"S"))) | T69: =IF(S$63="","",(COUNTIF(T$8:T$62,"S"))) | W69: =IF(V$63="","",(COUNTIF(W$8:W$62,"S"))) | AB69: =IF((COUNT($D69:$W69)=0),"",SUM($D69:$W69)) | AE69: =IF(OR(COUNTIF(AE8:AE62,"P")<>0,COUNTIF(AE8:AE62,"F")<>0,COUNTIF(AE8:AE62,"ab")<>0,COUNTIF(AE8:AE62,"Q1")<>0,COUNTIF(AE8:AE62,"Q2")<>0,COUNTIF(AE8:AE62,"R1")<>0,COUNTIF(AE8:AE62,"R2")<>0),(COUNTIF(AE8:AE62,"F")),"") | AF69: Total 'F's
C70: W | E70: =IF(D$63="","",(COUNTIF(E$8:E$62,"W"))) | G70: =IF(F$63="","",(COUNTIF(G$8:G$62,"W"))) | I70: =IF(H$63="","",(COUNTIF(I$8:I$62,"W"))) | K70: =IF(J$63="","",(COUNTIF(K$8:K$62,"W"))) | M70: =IF(L$63="","",(COUNTIF(M$8:M$62,"W"))) | O70: =IF(N$63="","",(COUNTIF(O$8:O$62,"W"))) | Q70: =IF(P$63="","",(COUNTIF(Q$8:Q$62,"W"))) | T70: =IF(S$63="","",(COUNTIF(T$8:T$62,"W"))) | W70: =IF(V$63="","",(COUNTIF(W$8:W$62,"W"))) | AC70: =IF((COUNT($D70:$W70)=0),"",SUM($D70:$W70)) | AE70: =IF(AND(AE63="",AE64="",AE65="",AE66="",AE67="",AE68="",AE69=""),"",SUM(AE63:AE69)) | AF70: Total
C71: AB | E71: =IF(D$63="","",(COUNTIF(E$8:E$62,"ab"))) | G71: =IF(F$63="","",(COUNTIF(G$8:G$62,"ab"))) | I71: =IF(H$63="","",(COUNTIF(I$8:I$62,"ab"))) | K71: =IF(J$63="","",(COUNTIF(K$8:K$62,"ab"))) | M71: =IF(L$63="","",(COUNTIF(M$8:M$62,"ab"))) | O71: =IF(N$63="","",(COUNTIF(O$8:O$62,"ab"))) | Q71: =IF(P$63="","",(COUNTIF(Q$8:Q$62,"ab"))) | T71: =IF(S$63="","",(COUNTIF(T$8:T$62,"ab"))) | W71: =IF(V$63="","",(COUNTIF(W$8:W$62,"ab"))) | AD71: =IF((COUNT($D71:$W71)=0),"",SUM($D71:$W71))
A72: Total | E72: =IF(D$63="","",(SUM(E$66:E$71))) | G72: =IF(F$63="","",(SUM(G$66:G$71))) | I72: =IF(H$63="","",(SUM(I$66:I$71))) | K72: =IF(J$63="","",(SUM(K$66:K$71))) | M72: =IF(L$63="","",(SUM(M$66:M$71))) | O72: =IF(N$63="","",(SUM(O$66:O$71))) | Q72: =IF(P$63="","",(SUM(Q$66:Q$71))) | T72: =IF(S$63="","",(SUM(T$66:T$71))) | W72: =IF(V$63="","",(SUM(W$66:W$71)))
C74: 30 - 39 | D74: =IF(D$63="","",(COUNTIFS(D$8:D$62,"<=39",D$8:D$62,">=30"))) | F74: =IF(F$63="","",(COUNTIFS(F$8:F$62,"<=39",F$8:F$62,">=30"))) | H74: =IF(H$63="","",(COUNTIFS(H$8:H$62,"<=39",H$8:H$62,">=30"))) | J74: =IF(J$63="","",(COUNTIFS(J$8:J$62,"<=39",J$8:J$62,">=30"))) | L74: =IF(L$63="","",(COUNTIFS(L$8:L$62,"<=39",L$8:L$62,">=30"))) | N74: =IF(N$63="","",(COUNTIFS(N$8:N$62,"<=39",N$8:N$62,">=30"))) | P74: =IF(P$63="","",(COUNTIFS(P$8:P$62,"<=39",P$8:P$62,">=30"))) | S74: =IF(S$63="","",(COUNTIFS(S$8:S$62,"<=39",S$8:S$62,">=30"))) | V74: =IF(V$63="","",(COUNTIFS(V$8:V$62,"<=39",V$8:V$62,">=30"))) | Z74: M - Marks | AE74: G - Grade
C75: 20 - 29 | D75: =IF(D$63="","",(COUNTIFS(D$8:D$62,"<=29",D$8:D$62,">=20"))) | F75: =IF(F$63="","",(COUNTIFS(F$8:F$62,"<=29",F$8:F$62,">=20"))) | H75: =IF(H$63="","",(COUNTIFS(H$8:H$62,"<=29",H$8:H$62,">=20"))) | J75: =IF(J$63="","",(COUNTIFS(J$8:J$62,"<=29",J$8:J$62,">=20"))) | L75: =IF(L$63="","",(COUNTIFS(L$8:L$62,"<=29",L$8:L$62,">=20"))) | N75: =IF(N$63="","",(COUNTIFS(N$8:N$62,"<=29",N$8:N$62,">=20"))) | P75: =IF(P$63="","",(COUNTIFS(P$8:P$62,"<=29",P$8:P$62,">=20"))) | S75: =IF(S$63="","",(COUNTIFS(S$8:S$62,"<=29",S$8:S$62,">=20"))) | V75: =IF(V$63="","",(COUNTIFS(V$8:V$62,"<=29",V$8:V$62,">=20"))) | Z75: Student's Group
C76: 10 - 19 | D76: =IF(D$63="","",(COUNTIFS(D$8:D$62,">=10",D$8:D$62,"<=19"))) | F76: =IF(F$63="","",(COUNTIFS(F$8:F$62,">=10",F$8:F$62,"<=19"))) | H76: =IF(H$63="","",(COUNTIFS(H$8:H$62,">=10",H$8:H$62,"<=19"))) | J76: =IF(J$63="","",(COUNTIFS(J$8:J$62,">=10",J$8:J$62,"<=19"))) | L76: =IF(L$63="","",(COUNTIFS(L$8:L$62,">=10",L$8:L$62,"<=19"))) | N76: =IF(N$63="","",(COUNTIFS(N$8:N$62,">=10",N$8:N$62,"<=19"))) | P76: =IF(P$63="","",(COUNTIFS(P$8:P$62,">=10",P$8:P$62,"<=19"))) | S76: =IF(S$63="","",(COUNTIFS(S$8:S$62,">=10",S$8:S$62,"<=19"))) | V76: =IF(V$63="","",(COUNTIFS(V$8:V$62,">=10",V$8:V$62,"<=19"))) | Z76: P | AA76: 6/3 or above with mathematics & first language
C77: 0 - 09 | D77: =IF(D$63="","",(COUNTIFS(D$8:D$62,">=0",D$8:D$62,"<=9"))) | F77: =IF(F$63="","",(COUNTIFS(F$8:F$62,">=0",F$8:F$62,"<=9"))) | H77: =IF(H$63="","",(COUNTIFS(H$8:H$62,">=0",H$8:H$62,"<=9"))) | J77: =IF(J$63="","",(COUNTIFS(J$8:J$62,">=0",J$8:J$62,"<=9"))) | L77: =IF(L$63="","",(COUNTIFS(L$8:L$62,">=0",L$8:L$62,"<=9"))) | N77: =IF(N$63="","",(COUNTIFS(N$8:N$62,">=0",N$8:N$62,"<=9"))) | P77: =IF(P$63="","",(COUNTIFS(P$8:P$62,">=0",P$8:P$62,"<=9"))) | S77: =IF(S$63="","",(COUNTIFS(S$8:S$62,">=0",S$8:S$62,"<=9"))) | V77: =IF(V$63="","",(COUNTIFS(V$8:V$62,">=0",V$8:V$62,"<=9"))) | Z77: Q1 | AA77: Need 1 credit pass (C) to reach level 'P'
Z78: Q2 | AA78: Need 1 ordinary pass (S) to reach level 'P'
B79: X | C79: Basket Subject Codes | Z79: R1 | AA79: Having > or = to 35 for 5 or more subjects
B80: Basket Subject I | D80: Basket Subject II | N80: Basket Subject III | Z80: R2 | AA80: Having > or = to 20 for 5 or more subjects
B81: X01 | C81: Geography | D81: X09 | F81: Art | N81: X17 | P81: ICT | Z81: F | AA81: Lower than 'R2' level
B82: X02 | C82: Citizenship Education | D82: X10 | F82: Western Music | N82: X18 | P82: Health & Physical Education | Y82: Date - | AB82: ………………………………
B83: X03 | C83: Entrepreneurial Education | D83: X11 | F83: Eastern Music | N83: X19 | P83: Agriculture & Food Technology
B84: X04 | C84: Business Studies & Accounts | D84: X12 | F84: Dancing | N84: X20 | P84: Home Economics | Y84: Class Teacher's Signature - | AC84: ………………………………
B85: X05 | D85: X13 | F85: Drama & Theatre | N85: X21 | P85: Art & Craft
...

Sheet B
A3: Student Achievement Levels of Grade 10 - 11
A4: Name of the School | S4: Zone | AC4: Division
A5: Grade & Class | J5: Year | S5: Term
B6: Student ID | C6: Subjects | D6: Mathematics | F6: Science | H6: First Language | J6: English | L6: Religion | N6: History | P6: Basket Subject I | S6: Basket Subject II | V6: Basket Subject III | Y6: Student's Grade Total | AD6: Pass=P /Fail=F | AE6: Student's Group | AF6: Student's Total | AG6: Student's Average | AH6: Student's Position
C7: Student's Name | D7: M | E7: G | F7: M | G7: G | H7: M | I7: G | J7: M | K7: G | L7: M | M7: G | N7: M | O7: G | P7: M | Q7: G | R7: X | S7: M | T7: G | U7: X | V7: M | W7: G | X7: X | Y7: A | Z7: B | AA7: C | AB7: S | AC7: W
A8: 1 | E8: =IF(D8="","",IF(D8="ab","ab",IF(D8>=75,"A",(IF(D8>=65,"B",IF(D8>=50,"C",IF(D8>=40,"S","W"))))))) | G8: =IF(F8="","",IF(F8="ab","ab",IF(F8>=75,"A",(IF(F8>=65,"B",IF(F8>=50,"C",IF(F8>=40,"S","W"))))))) | I8: =IF(H8="","",IF(H8="ab","ab",IF(H8>=75,"A",(IF(H8>=65,"B",IF(H8>=50,"C",IF(H8>=40,"S","W"))))))) | K8: =IF(J8="","",IF(J8="ab","ab",IF(J8>=75,"A",(IF(J8>=65,"B",IF(J8>=50,"C",IF(J8>=40,"S","W"))))))) | M8: =IF(L8="","",IF(L8="ab","ab",IF(L8>=75,"A",(IF(L8>=65,"B",IF(L8>=50,"C",IF(L8>=40,"S","W"))))))) | O8: =IF(N8="","",IF(N8="ab","ab",IF(N8>=75,"A",(IF(N8>=65,"B",IF(N8>=50,"C",IF(N8>=40,"S","W"))))))) | Q8: =IF(P8="","",IF(P8="ab","ab",IF(P8>=75,"A",(IF(P8>=65,"B",IF(P8>=50,"C",IF(P8>=40,"S","W"))))))) | T8: =IF(S8="","",IF(S8="ab","ab",IF(S8>=75,"A",(IF(S8>=65,"B",IF(S8>=50,"C",IF(S8>=40,"S","W"))))))) | W8: =IF(V8="","",IF(V8="ab","ab",IF(V8>=75,"A",(IF(V8>=65,"B",IF(V8>=50,"C",IF(V8>=40,"S","W"))))))) | Y8: =IF(AND($D8="ab",$F8="ab",$H8="ab",$J8="ab",$L8="ab",$N8="ab",$P8="ab",$S8="ab",$V8="ab"),"-",IF(COUNT($D8:$W8)=0,"",(COUNTIF($D8:$W8,"A")))) | Z8: =IF(AND($D8="ab",$F8="ab",$H8="ab",$J8="ab",$L8="ab",$N8="ab",$P8="ab",$S8="ab",$V8="ab"),"-",IF(COUNT($D8:$W8)=0,"",(COUNTIF($D8:$W8,"B")))) | AA8: =IF(AND($D8="ab",$F8="ab",$H8="ab",$J8="ab",$L8="ab",$N8="ab",$P8="ab",$S8="ab",$V8="ab"),"-",IF(COUNT($D8:$W8)=0,"",(COUNTIF($D8:$W8,"C")))) | AB8: =IF(AND($D8="ab",$F8="ab",$H8="ab",$J8="ab",$L8="ab",$N8="ab",$P8="ab",$S8="ab",$V8="ab"),"-",IF(COUNT($D8:$W8)=0,"",(COUNTIF($D8:$W8,"S")))) | AC8: =IF(AND($D8="ab",$F8="ab",$H8="ab",$J8="ab",$L8="ab",$N8="ab",$P8="ab",$S8="ab",$V8="ab"),"-",IF(COUNT($D8:$W8)=0,"",(COUNTIF($D8:$W8,"W")))) | AD8: =IF(AND(D8="ab",F8="ab",H8="ab",J8="ab",L8="ab",N8="ab",P8="ab",S8="ab",V8="ab"),"ab",IF(AND(Y8="",Z8="",AA8="",AB8="",AC8=""),"",IF(AND((D8>=40),(H8>=40),(Y8+Z8+AA8+AB8)>=6,(Y8+Z8+AA8)>=3),"P","F"))) | AE8: =IF(AD8="","",IF(AD8="P","P",IF(AND(AD8="F",H8>=40,D8>=40,(Y8+Z8+AA8+AB8)>=6,(Y8+Z8+AA8)=2),"Q1",IF(AND(AD8="F",(OR(H8>=40,D8>=40)),(Y8+Z8+AA8+AB8)>=5,(Y8+Z8+AA8)>=3),"Q2",IF((COUNTIF(D8:X8,">=40"))>=5,"R1",IF((COUNTIF(D8:X8,">=20"))>=5,"R2","F")))))) | AF8: =IF(AND(D8="",F8="",H8="",J8="",L8="",N8="",P8="",S8="",V8=""),"",IF(AND(D8="ab",F8="ab",H8="ab",J8="ab",L8="ab",N8="ab",P8="ab",S8="ab",V8="ab"),"ab",IF(COUNT(D8:W8)=0,"",(SUM(D8:V8))))) | AG8: =IF(AF8="","",IF(AF8="ab","ab",IF(AF8=0,0,(AVERAGE(D8:V8))))) | AH8: =IF(AF8="","",IF(AF8="ab","ab",(RANK(AF8,$AF$8:$AF$62))))
A9: 2 | E9: =IF(D9="","",IF(D9="ab","ab",IF(D9>=75,"A",(IF(D9>=65,"B",IF(D9>=50,"C",IF(D9>=40,"S","W"))))))) | G9: =IF(F9="","",IF(F9="ab","ab",IF(F9>=75,"A",(IF(F9>=65,"B",IF(F9>=50,"C",IF(F9>=40,"S","W"))))))) | I9: =IF(H9="","",IF(H9="ab","ab",IF(H9>=75,"A",(IF(H9>=65,"B",IF(H9>=50,"C",IF(H9>=40,"S","W"))))))) | K9: =IF(J9="","",IF(J9="ab","ab",IF(J9>=75,"A",(IF(J9>=65,"B",IF(J9>=50,"C",IF(J9>=40,"S","W"))))))) | M9: =IF(L9="","",IF(L9="ab","ab",IF(L9>=75,"A",(IF(L9>=65,"B",IF(L9>=50,"C",IF(L9>=40,"S","W"))))))) | O9: =IF(N9="","",IF(N9="ab","ab",IF(N9>=75,"A",(IF(N9>=65,"B",IF(N9>=50,"C",IF(N9>=40,"S","W"))))))) | Q9: =IF(P9="","",IF(P9="ab","ab",IF(P9>=75,"A",(IF(P9>=65,"B",IF(P9>=50,"C",IF(P9>=40,"S","W"))))))) | T9: =IF(S9="","",IF(S9="ab","ab",IF(S9>=75,"A",(IF(S9>=65,"B",IF(S9>=50,"C",IF(S9>=40,"S","W"))))))) | W9: =IF(V9="","",IF(V9="ab","ab",IF(V9>=75,"A",(IF(V9>=65,"B",IF(V9>=50,"C",IF(V9>=40,"S","W"))))))) | Y9: =IF(AND($D9="ab",$F9="ab",$H9="ab",$J9="ab",$L9="ab",$N9="ab",$P9="ab",$S9="ab",$V9="ab"),"-",IF(COUNT($D9:$W9)=0,"",(COUNTIF($D9:$W9,"A")))) | Z9: =IF(AND($D9="ab",$F9="ab",$H9="ab",$J9="ab",$L9="ab",$N9="ab",$P9="ab",$S9="ab",$V9="ab"),"-",IF(COUNT($D9:$W9)=0,"",(COUNTIF($D9:$W9,"B")))) | AA9: =IF(AND($D9="ab",$F9="ab",$H9="ab",$J9="ab",$L9="ab",$N9="ab",$P9="ab",$S9="ab",$V9="ab"),"-",IF(COUNT($D9:$W9)=0,"",(COUNTIF($D9:$W9,"C")))) | AB9: =IF(AND($D9="ab",$F9="ab",$H9="ab",$J9="ab",$L9="ab",$N9="ab",$P9="ab",$S9="ab",$V9="ab"),"-",IF(COUNT($D9:$W9)=0,"",(COUNTIF($D9:$W9,"S")))) | AC9: =IF(AND($D9="ab",$F9="ab",$H9="ab",$J9="ab",$L9="ab",$N9="ab",$P9="ab",$S9="ab",$V9="ab"),"-",IF(COUNT($D9:$W9)=0,"",(COUNTIF($D9:$W9,"W")))) | AD9: =IF(AND(D9="ab",F9="ab",H9="ab",J9="ab",L9="ab",N9="ab",P9="ab",S9="ab",V9="ab"),"ab",IF(AND(Y9="",Z9="",AA9="",AB9="",AC9=""),"",IF(AND((D9>=40),(H9>=40),(Y9+Z9+AA9+AB9)>=6,(Y9+Z9+AA9)>=3),"P","F"))) | AE9: =IF(AD9="","",IF(AD9="P","P",IF(AND(AD9="F",H9>=40,D9>=40,(Y9+Z9+AA9+AB9)>=6,(Y9+Z9+AA9)=2),"Q1",IF(AND(AD9="F",(OR(H9>=40,D9>=40)),(Y9+Z9+AA9+AB9)>=5,(Y9+Z9+AA9)>=3),"Q2",IF((COUNTIF(D9:X9,">=40"))>=5,"R1",IF((COUNTIF(D9:X9,">=20"))>=5,"R2","F")))))) | AF9: =IF(AND(D9="",F9="",H9="",J9="",L9="",N9="",P9="",S9="",V9=""),"",IF(AND(D9="ab",F9="ab",H9="ab",J9="ab",L9="ab",N9="ab",P9="ab",S9="ab",V9="ab"),"ab",IF(COUNT(D9:W9)=0,"",(SUM(D9:V9))))) | AG9: =IF(AF9="","",IF(AF9="ab","ab",IF(AF9=0,0,(AVERAGE(D9:V9))))) | AH9: =IF(AF9="","",IF(AF9="ab","ab",(RANK(AF9,$AF$8:$AF$62))))
A10: 3 | E10: =IF(D10="","",IF(D10="ab","ab",IF(D10>=75,"A",(IF(D10>=65,"B",IF(D10>=50,"C",IF(D10>=40,"S","W"))))))) | G10: =IF(F10="","",IF(F10="ab","ab",IF(F10>=75,"A",(IF(F10>=65,"B",IF(F10>=50,"C",IF(F10>=40,"S","W"))))))) | I10: =IF(H10="","",IF(H10="ab","ab",IF(H10>=75,"A",(IF(H10>=65,"B",IF(H10>=50,"C",IF(H10>=40,"S","W"))))))) | K10: =IF(J10="","",IF(J10="ab","ab",IF(J10>=75,"A",(IF(J10>=65,"B",IF(J10>=50,"C",IF(J10>=40,"S","W"))))))) | M10: =IF(L10="","",IF(L10="ab","ab",IF(L10>=75,"A",(IF(L10>=65,"B",IF(L10>=50,"C",IF(L10>=40,"S","W"))))))) | O10: =IF(N10="","",IF(N10="ab","ab",IF(N10>=75,"A",(IF(N10>=65,"B",IF(N10>=50,"C",IF(N10>=40,"S","W"))))))) | Q10: =IF(P10="","",IF(P10="ab","ab",IF(P10>=75,"A",(IF(P10>=65,"B",IF(P10>=50,"C",IF(P10>=40,"S","W"))))))) | T10: =IF(S10="","",IF(S10="ab","ab",IF(S10>=75,"A",(IF(S10>=65,"B",IF(S10>=50,"C",IF(S10>=40,"S","W"))))))) | W10: =IF(V10="","",IF(V10="ab","ab",IF(V10>=75,"A",(IF(V10>=65,"B",IF(V10>=50,"C",IF(V10>=40,"S","W"))))))) | Y10: =IF(AND($D10="ab",$F10="ab",$H10="ab",$J10="ab",$L10="ab",$N10="ab",$P10="ab",$S10="ab",$V10="ab"),"-",IF(COUNT($D10:$W10)=0,"",(COUNTIF($D10:$W10,"A")))) | Z10: =IF(AND($D10="ab",$F10="ab",$H10="ab",$J10="ab",$L10="ab",$N10="ab",$P10="ab",$S10="ab",$V10="ab"),"-",IF(COUNT($D10:$W10)=0,"",(COUNTIF($D10:$W10,"B")))) | AA10: =IF(AND($D10="ab",$F10="ab",$H10="ab",$J10="ab",$L10="ab",$N10="ab",$P10="ab",$S10="ab",$V10="ab"),"-",IF(COUNT($D10:$W10)=0,"",(COUNTIF($D10:$W10,"C")))) | AB10: =IF(AND($D10="ab",$F10="ab",$H10="ab",$J10="ab",$L10="ab",$N10="ab",$P10="ab",$S10="ab",$V10="ab"),"-",IF(COUNT($D10:$W10)=0,"",(COUNTIF($D10:$W10,"S")))) | AC10: =IF(AND($D10="ab",$F10="ab",$H10="ab",$J10="ab",$L10="ab",$N10="ab",$P10="ab",$S10="ab",$V10="ab"),"-",IF(COUNT($D10:$W10)=0,"",(COUNTIF($D10:$W10,"W")))) | AD10: =IF(AND(D10="ab",F10="ab",H10="ab",J10="ab",L10="ab",N10="ab",P10="ab",S10="ab",V10="ab"),"ab",IF(AND(Y10="",Z10="",AA10="",AB10="",AC10=""),"",IF(AND((D10>=40),(H10>=40),(Y10+Z10+AA10+AB10)>=6,(Y10+Z10+AA10)>=3),"P","F"))) | AE10: =IF(AD10="","",IF(AD10="P","P",IF(AND(AD10="F",H10>=40,D10>=40,(Y10+Z10+AA10+AB10)>=6,(Y10+Z10+AA10)=2),"Q1",IF(AND(AD10="F",(OR(H10>=40,D10>=40)),(Y10+Z10+AA10+AB10)>=5,(Y10+Z10+AA10)>=3),"Q2",IF((COUNTIF(D10:X10,">=40"))>=5,"R1",IF((COUNTIF(D10:X10,">=20"))>=5,"R2","F")))))) | AF10: =IF(AND(D10="",F10="",H10="",J10="",L10="",N10="",P10="",S10="",V10=""),"",IF(AND(D10="ab",F10="ab",H10="ab",J10="ab",L10="ab",N10="ab",P10="ab",S10="ab",V10="ab"),"ab",IF(COUNT(D10:W10)=0,"",(SUM(D10:V10))))) | AG10: =IF(AF10="","",IF(AF10="ab","ab",IF(AF10=0,0,(AVERAGE(D10:V10))))) | AH10: =IF(AF10="","",IF(AF10="ab","ab",(RANK(AF10,$AF$8:$AF$62))))
A11: 4 | E11: =IF(D11="","",IF(D11="ab","ab",IF(D11>=75,"A",(IF(D11>=65,"B",IF(D11>=50,"C",IF(D11>=40,"S","W"))))))) | G11: =IF(F11="","",IF(F11="ab","ab",IF(F11>=75,"A",(IF(F11>=65,"B",IF(F11>=50,"C",IF(F11>=40,"S","W"))))))) | I11: =IF(H11="","",IF(H11="ab","ab",IF(H11>=75,"A",(IF(H11>=65,"B",IF(H11>=50,"C",IF(H11>=40,"S","W"))))))) | K11: =IF(J11="","",IF(J11="ab","ab",IF(J11>=75,"A",(IF(J11>=65,"B",IF(J11>=50,"C",IF(J11>=40,"S","W"))))))) | M11: =IF(L11="","",IF(L11="ab","ab",IF(L11>=75,"A",(IF(L11>=65,"B",IF(L11>=50,"C",IF(L11>=40,"S","W"))))))) | O11: =IF(N11="","",IF(N11="ab","ab",IF(N11>=75,"A",(IF(N11>=65,"B",IF(N11>=50,"C",IF(N11>=40,"S","W"))))))) | Q11: =IF(P11="","",IF(P11="ab","ab",IF(P11>=75,"A",(IF(P11>=65,"B",IF(P11>=50,"C",IF(P11>=40,"S","W"))))))) | T11: =IF(S11="","",IF(S11="ab","ab",IF(S11>=75,"A",(IF(S11>=65,"B",IF(S11>=50,"C",IF(S11>=40,"S","W"))))))) | W11: =IF(V11="","",IF(V11="ab","ab",IF(V11>=75,"A",(IF(V11>=65,"B",IF(V11>=50,"C",IF(V11>=40,"S","W"))))))) | Y11: =IF(AND($D11="ab",$F11="ab",$H11="ab",$J11="ab",$L11="ab",$N11="ab",$P11="ab",$S11="ab",$V11="ab"),"-",IF(COUNT($D11:$W11)=0,"",(COUNTIF($D11:$W11,"A")))) | Z11: =IF(AND($D11="ab",$F11="ab",$H11="ab",$J11="ab",$L11="ab",$N11="ab",$P11="ab",$S11="ab",$V11="ab"),"-",IF(COUNT($D11:$W11)=0,"",(COUNTIF($D11:$W11,"B")))) | AA11: =IF(AND($D11="ab",$F11="ab",$H11="ab",$J11="ab",$L11="ab",$N11="ab",$P11="ab",$S11="ab",$V11="ab"),"-",IF(COUNT($D11:$W11)=0,"",(COUNTIF($D11:$W11,"C")))) | AB11: =IF(AND($D11="ab",$F11="ab",$H11="ab",$J11="ab",$L11="ab",$N11="ab",$P11="ab",$S11="ab",$V11="ab"),"-",IF(COUNT($D11:$W11)=0,"",(COUNTIF($D11:$W11,"S")))) | AC11: =IF(AND($D11="ab",$F11="ab",$H11="ab",$J11="ab",$L11="ab",$N11="ab",$P11="ab",$S11="ab",$V11="ab"),"-",IF(COUNT($D11:$W11)=0,"",(COUNTIF($D11:$W11,"W")))) | AD11: =IF(AND(D11="ab",F11="ab",H11="ab",J11="ab",L11="ab",N11="ab",P11="ab",S11="ab",V11="ab"),"ab",IF(AND(Y11="",Z11="",AA11="",AB11="",AC11=""),"",IF(AND((D11>=40),(H11>=40),(Y11+Z11+AA11+AB11)>=6,(Y11+Z11+AA11)>=3),"P","F"))) | AE11: =IF(AD11="","",IF(AD11="P","P",IF(AND(AD11="F",H11>=40,D11>=40,(Y11+Z11+AA11+AB11)>=6,(Y11+Z11+AA11)=2),"Q1",IF(AND(AD11="F",(OR(H11>=40,D11>=40)),(Y11+Z11+AA11+AB11)>=5,(Y11+Z11+AA11)>=3),"Q2",IF((COUNTIF(D11:X11,">=40"))>=5,"R1",IF((COUNTIF(D11:X11,">=20"))>=5,"R2","F")))))) | AF11: =IF(AND(D11="",F11="",H11="",J11="",L11="",N11="",P11="",S11="",V11=""),"",IF(AND(D11="ab",F11="ab",H11="ab",J11="ab",L11="ab",N11="ab",P11="ab",S11="ab",V11="ab"),"ab",IF(COUNT(D11:W11)=0,"",(SUM(D11:V11))))) | AG11: =IF(AF11="","",IF(AF11="ab","ab",IF(AF11=0,0,(AVERAGE(D11:V11))))) | AH11: =IF(AF11="","",IF(AF11="ab","ab",(RANK(AF11,$AF$8:$AF$62))))
A12: 5 | E12: =IF(D12="","",IF(D12="ab","ab",IF(D12>=75,"A",(IF(D12>=65,"B",IF(D12>=50,"C",IF(D12>=40,"S","W"))))))) | G12: =IF(F12="","",IF(F12="ab","ab",IF(F12>=75,"A",(IF(F12>=65,"B",IF(F12>=50,"C",IF(F12>=40,"S","W"))))))) | I12: =IF(H12="","",IF(H12="ab","ab",IF(H12>=75,"A",(IF(H12>=65,"B",IF(H12>=50,"C",IF(H12>=40,"S","W"))))))) | K12: =IF(J12="","",IF(J12="ab","ab",IF(J12>=75,"A",(IF(J12>=65,"B",IF(J12>=50,"C",IF(J12>=40,"S","W"))))))) | M12: =IF(L12="","",IF(L12="ab","ab",IF(L12>=75,"A",(IF(L12>=65,"B",IF(L12>=50,"C",IF(L12>=40,"S","W"))))))) | O12: =IF(N12="","",IF(N12="ab","ab",IF(N12>=75,"A",(IF(N12>=65,"B",IF(N12>=50,"C",IF(N12>=40,"S","W"))))))) | Q12: =IF(P12="","",IF(P12="ab","ab",IF(P12>=75,"A",(IF(P12>=65,"B",IF(P12>=50,"C",IF(P12>=40,"S","W"))))))) | T12: =IF(S12="","",IF(S12="ab","ab",IF(S12>=75,"A",(IF(S12>=65,"B",IF(S12>=50,"C",IF(S12>=40,"S","W"))))))) | W12: =IF(V12="","",IF(V12="ab","ab",IF(V12>=75,"A",(IF(V12>=65,"B",IF(V12>=50,"C",IF(V12>=40,"S","W"))))))) | Y12: =IF(AND($D12="ab",$F12="ab",$H12="ab",$J12="ab",$L12="ab",$N12="ab",$P12="ab",$S12="ab",$V12="ab"),"-",IF(COUNT($D12:$W12)=0,"",(COUNTIF($D12:$W12,"A")))) | Z12: =IF(AND($D12="ab",$F12="ab",$H12="ab",$J12="ab",$L12="ab",$N12="ab",$P12="ab",$S12="ab",$V12="ab"),"-",IF(COUNT($D12:$W12)=0,"",(COUNTIF($D12:$W12,"B")))) | AA12: =IF(AND($D12="ab",$F12="ab",$H12="ab",$J12="ab",$L12="ab",$N12="ab",$P12="ab",$S12="ab",$V12="ab"),"-",IF(COUNT($D12:$W12)=0,"",(COUNTIF($D12:$W12,"C")))) | AB12: =IF(AND($D12="ab",$F12="ab",$H12="ab",$J12="ab",$L12="ab",$N12="ab",$P12="ab",$S12="ab",$V12="ab"),"-",IF(COUNT($D12:$W12)=0,"",(COUNTIF($D12:$W12,"S")))) | AC12: =IF(AND($D12="ab",$F12="ab",$H12="ab",$J12="ab",$L12="ab",$N12="ab",$P12="ab",$S12="ab",$V12="ab"),"-",IF(COUNT($D12:$W12)=0,"",(COUNTIF($D12:$W12,"W")))) | AD12: =IF(AND(D12="ab",F12="ab",H12="ab",J12="ab",L12="ab",N12="ab",P12="ab",S12="ab",V12="ab"),"ab",IF(AND(Y12="",Z12="",AA12="",AB12="",AC12=""),"",IF(AND((D12>=40),(H12>=40),(Y12+Z12+AA12+AB12)>=6,(Y12+Z12+AA12)>=3),"P","F"))) | AE12: =IF(AD12="","",IF(AD12="P","P",IF(AND(AD12="F",H12>=40,D12>=40,(Y12+Z12+AA12+AB12)>=6,(Y12+Z12+AA12)=2),"Q1",IF(AND(AD12="F",(OR(H12>=40,D12>=40)),(Y12+Z12+AA12+AB12)>=5,(Y12+Z12+AA12)>=3),"Q2",IF((COUNTIF(D12:X12,">=40"))>=5,"R1",IF((COUNTIF(D12:X12,">=20"))>=5,"R2","F")))))) | AF12: =IF(AND(D12="",F12="",H12="",J12="",L12="",N12="",P12="",S12="",V12=""),"",IF(AND(D12="ab",F12="ab",H12="ab",J12="ab",L12="ab",N12="ab",P12="ab",S12="ab",V12="ab"),"ab",IF(COUNT(D12:W12)=0,"",(SUM(D12:V12))))) | AG12: =IF(AF12="","",IF(AF12="ab","ab",IF(AF12=0,0,(AVERAGE(D12:V12))))) | AH12: =IF(AF12="","",IF(AF12="ab","ab",(RANK(AF12,$AF$8:$AF$62))))
